[2023-12-17T15:16:56.921+0000] {taskinstance.py:1157} INFO - Dependencies all met for dep_context=non-requeueable deps ti=<TaskInstance: read_s3_data.read_s3_data scheduled__2022-09-11T00:00:00+00:00 [queued]>
[2023-12-17T15:16:57.037+0000] {taskinstance.py:1157} INFO - Dependencies all met for dep_context=requeueable deps ti=<TaskInstance: read_s3_data.read_s3_data scheduled__2022-09-11T00:00:00+00:00 [queued]>
[2023-12-17T15:16:57.046+0000] {taskinstance.py:1359} INFO - Starting attempt 1 of 4
[2023-12-17T15:16:57.165+0000] {taskinstance.py:1380} INFO - Executing <Task(PythonOperator): read_s3_data> on 2022-09-11 00:00:00+00:00
[2023-12-17T15:16:57.382+0000] {standard_task_runner.py:57} INFO - Started process 26142 to run task
[2023-12-17T15:16:57.440+0000] {standard_task_runner.py:84} INFO - Running: ['***', 'tasks', 'run', 'read_s3_data', 'read_s3_data', 'scheduled__2022-09-11T00:00:00+00:00', '--job-id', '6432', '--raw', '--subdir', 'DAGS_FOLDER/read.py', '--cfg-path', '/tmp/tmptg8wt4xo']
[2023-12-17T15:16:57.458+0000] {standard_task_runner.py:85} INFO - Job 6432: Subtask read_s3_data
[2023-12-17T15:16:59.342+0000] {task_command.py:415} INFO - Running <TaskInstance: read_s3_data.read_s3_data scheduled__2022-09-11T00:00:00+00:00 [running]> on host 533efb53d454
[2023-12-17T15:17:05.342+0000] {taskinstance.py:1660} INFO - Exporting env vars: AIRFLOW_CTX_DAG_OWNER='***' AIRFLOW_CTX_DAG_ID='read_s3_data' AIRFLOW_CTX_TASK_ID='read_s3_data' AIRFLOW_CTX_EXECUTION_DATE='2022-09-11T00:00:00+00:00' AIRFLOW_CTX_TRY_NUMBER='1' AIRFLOW_CTX_DAG_RUN_ID='scheduled__2022-09-11T00:00:00+00:00'
[2023-12-17T15:17:05.485+0000] {taskinstance.py:1935} ERROR - Task failed with exception
Traceback (most recent call last):
  File "/home/airflow/.local/lib/python3.11/site-packages/airflow/operators/python.py", line 192, in execute
    return_value = self.execute_callable()
                   ^^^^^^^^^^^^^^^^^^^^^^^
  File "/home/airflow/.local/lib/python3.11/site-packages/airflow/operators/python.py", line 209, in execute_callable
    return self.python_callable(*self.op_args, **self.op_kwargs)
           ^^^^^^^^^^^^^^^^^^^^^^^^^^^^^^^^^^^^^^^^^^^^^^^^^^^^^
TypeError: generic_s3_clients() missing 2 required positional arguments: 'ACCESS_KEY' and 'SECRET_KEY'
[2023-12-17T15:17:05.629+0000] {taskinstance.py:1398} INFO - Marking task as UP_FOR_RETRY. dag_id=read_s3_data, task_id=read_s3_data, execution_date=20220911T000000, start_date=20231217T151656, end_date=20231217T151705
[2023-12-17T15:17:05.924+0000] {standard_task_runner.py:104} ERROR - Failed to execute job 6432 for task read_s3_data (generic_s3_clients() missing 2 required positional arguments: 'ACCESS_KEY' and 'SECRET_KEY'; 26142)
[2023-12-17T15:17:07.809+0000] {local_task_job_runner.py:228} INFO - Task exited with return code 1
[2023-12-17T15:17:08.984+0000] {taskinstance.py:2776} INFO - 0 downstream tasks scheduled from follow-on schedule check
[2023-12-24T17:01:42.397+0000] {taskinstance.py:1157} INFO - Dependencies all met for dep_context=non-requeueable deps ti=<TaskInstance: read_s3_data.read_s3_data scheduled__2022-09-11T00:00:00+00:00 [queued]>
[2023-12-24T17:01:42.412+0000] {taskinstance.py:1157} INFO - Dependencies all met for dep_context=requeueable deps ti=<TaskInstance: read_s3_data.read_s3_data scheduled__2022-09-11T00:00:00+00:00 [queued]>
[2023-12-24T17:01:42.414+0000] {taskinstance.py:1359} INFO - Starting attempt 1 of 4
[2023-12-24T17:01:42.440+0000] {taskinstance.py:1380} INFO - Executing <Task(PythonOperator): read_s3_data> on 2022-09-11 00:00:00+00:00
[2023-12-24T17:01:42.454+0000] {standard_task_runner.py:57} INFO - Started process 681 to run task
[2023-12-24T17:01:42.466+0000] {standard_task_runner.py:84} INFO - Running: ['***', 'tasks', 'run', 'read_s3_data', 'read_s3_data', 'scheduled__2022-09-11T00:00:00+00:00', '--job-id', '153', '--raw', '--subdir', 'DAGS_FOLDER/read.py', '--cfg-path', '/tmp/tmpy4b1scq7']
[2023-12-24T17:01:42.475+0000] {standard_task_runner.py:85} INFO - Job 153: Subtask read_s3_data
[2023-12-24T17:01:42.744+0000] {task_command.py:415} INFO - Running <TaskInstance: read_s3_data.read_s3_data scheduled__2022-09-11T00:00:00+00:00 [running]> on host 37dc6044b459
[2023-12-24T17:01:42.976+0000] {taskinstance.py:1660} INFO - Exporting env vars: AIRFLOW_CTX_DAG_OWNER='***' AIRFLOW_CTX_DAG_ID='read_s3_data' AIRFLOW_CTX_TASK_ID='read_s3_data' AIRFLOW_CTX_EXECUTION_DATE='2022-09-11T00:00:00+00:00' AIRFLOW_CTX_TRY_NUMBER='1' AIRFLOW_CTX_DAG_RUN_ID='scheduled__2022-09-11T00:00:00+00:00'
[2023-12-24T17:01:43.013+0000] {taskinstance.py:1935} ERROR - Task failed with exception
Traceback (most recent call last):
  File "/home/airflow/.local/lib/python3.11/site-packages/airflow/operators/python.py", line 192, in execute
    return_value = self.execute_callable()
                   ^^^^^^^^^^^^^^^^^^^^^^^
  File "/home/airflow/.local/lib/python3.11/site-packages/airflow/operators/python.py", line 209, in execute_callable
    return self.python_callable(*self.op_args, **self.op_kwargs)
           ^^^^^^^^^^^^^^^^^^^^^^^^^^^^^^^^^^^^^^^^^^^^^^^^^^^^^
  File "/opt/airflow/dags/read.py", line 29, in read_s3_file
    session = boto3.session.Session(aws_access_key_id=Variable.get('ACCESS_KEY'),
                                                     ^^^^^^^^^^^^^^^^^^^^^^^^^^
  File "/home/airflow/.local/lib/python3.11/site-packages/airflow/models/variable.py", line 140, in get
    raise KeyError(f"Variable {key} does not exist")
KeyError: 'Variable ACCESS_KEY does not exist'
[2023-12-24T17:01:43.046+0000] {taskinstance.py:1398} INFO - Marking task as UP_FOR_RETRY. dag_id=read_s3_data, task_id=read_s3_data, execution_date=20220911T000000, start_date=20231224T170142, end_date=20231224T170143
[2023-12-24T17:01:43.095+0000] {standard_task_runner.py:104} ERROR - Failed to execute job 153 for task read_s3_data ('Variable ACCESS_KEY does not exist'; 681)
[2023-12-24T17:01:43.146+0000] {local_task_job_runner.py:228} INFO - Task exited with return code 1
[2023-12-24T17:01:43.434+0000] {taskinstance.py:2776} INFO - 0 downstream tasks scheduled from follow-on schedule check
