[2023-04-19T12:36:07.031+0000] {taskinstance.py:1083} INFO - Dependencies all met for <TaskInstance: age_check.age_check scheduled__2022-08-11T00:00:00+00:00 [queued]>
[2023-04-19T12:36:07.073+0000] {taskinstance.py:1083} INFO - Dependencies all met for <TaskInstance: age_check.age_check scheduled__2022-08-11T00:00:00+00:00 [queued]>
[2023-04-19T12:36:07.075+0000] {taskinstance.py:1279} INFO - 
--------------------------------------------------------------------------------
[2023-04-19T12:36:07.076+0000] {taskinstance.py:1280} INFO - Starting attempt 2 of 4
[2023-04-19T12:36:07.078+0000] {taskinstance.py:1281} INFO - 
--------------------------------------------------------------------------------
[2023-04-19T12:36:07.106+0000] {taskinstance.py:1300} INFO - Executing <Task(PythonOperator): age_check> on 2022-08-11 00:00:00+00:00
[2023-04-19T12:36:07.124+0000] {standard_task_runner.py:55} INFO - Started process 21263 to run task
[2023-04-19T12:36:07.156+0000] {standard_task_runner.py:82} INFO - Running: ['***', 'tasks', 'run', 'age_check', 'age_check', 'scheduled__2022-08-11T00:00:00+00:00', '--job-id', '512', '--raw', '--subdir', 'DAGS_FOLDER/age.py', '--cfg-path', '/tmp/tmpr15hkqs1']
[2023-04-19T12:36:07.158+0000] {standard_task_runner.py:83} INFO - Job 512: Subtask age_check
[2023-04-19T12:36:07.343+0000] {task_command.py:388} INFO - Running <TaskInstance: age_check.age_check scheduled__2022-08-11T00:00:00+00:00 [running]> on host fe34f61acbb3
[2023-04-19T12:36:07.544+0000] {taskinstance.py:1509} INFO - Exporting the following env vars:
AIRFLOW_CTX_DAG_OWNER=***
AIRFLOW_CTX_DAG_ID=age_check
AIRFLOW_CTX_TASK_ID=age_check
AIRFLOW_CTX_EXECUTION_DATE=2022-08-11T00:00:00+00:00
AIRFLOW_CTX_TRY_NUMBER=2
AIRFLOW_CTX_DAG_RUN_ID=scheduled__2022-08-11T00:00:00+00:00
[2023-04-19T12:36:07.574+0000] {taskinstance.py:1768} ERROR - Task failed with exception
Traceback (most recent call last):
  File "/home/airflow/.local/lib/python3.7/site-packages/airflow/operators/python.py", line 175, in execute
    return_value = self.execute_callable()
  File "/home/airflow/.local/lib/python3.7/site-packages/airflow/operators/python.py", line 192, in execute_callable
    return self.python_callable(*self.op_args, **self.op_kwargs)
  File "/opt/airflow/dags/age.py", line 35, in age_check
    birth_year = int(Variable.get('birth_year'))
  File "/home/airflow/.local/lib/python3.7/site-packages/airflow/models/variable.py", line 141, in get
    raise KeyError(f"Variable {key} does not exist")
KeyError: 'Variable birth_year does not exist'
[2023-04-19T12:36:07.620+0000] {taskinstance.py:1323} INFO - Marking task as UP_FOR_RETRY. dag_id=age_check, task_id=age_check, execution_date=20220811T000000, start_date=20230419T123607, end_date=20230419T123607
[2023-04-19T12:36:07.653+0000] {standard_task_runner.py:105} ERROR - Failed to execute job 512 for task age_check ('Variable birth_year does not exist'; 21263)
[2023-04-19T12:36:07.719+0000] {local_task_job.py:208} INFO - Task exited with return code 1
[2023-04-19T12:36:07.913+0000] {taskinstance.py:2578} INFO - 0 downstream tasks scheduled from follow-on schedule check
[2023-05-17T09:51:56.397+0000] {taskinstance.py:1083} INFO - Dependencies all met for <TaskInstance: age_check.age_check scheduled__2022-08-11T00:00:00+00:00 [queued]>
[2023-05-17T09:51:56.433+0000] {taskinstance.py:1083} INFO - Dependencies all met for <TaskInstance: age_check.age_check scheduled__2022-08-11T00:00:00+00:00 [queued]>
[2023-05-17T09:51:56.435+0000] {taskinstance.py:1279} INFO - 
--------------------------------------------------------------------------------
[2023-05-17T09:51:56.437+0000] {taskinstance.py:1280} INFO - Starting attempt 2 of 4
[2023-05-17T09:51:56.441+0000] {taskinstance.py:1281} INFO - 
--------------------------------------------------------------------------------
[2023-05-17T09:51:56.478+0000] {taskinstance.py:1300} INFO - Executing <Task(PythonOperator): age_check> on 2022-08-11 00:00:00+00:00
[2023-05-17T09:51:56.489+0000] {standard_task_runner.py:55} INFO - Started process 3962 to run task
[2023-05-17T09:51:56.495+0000] {standard_task_runner.py:82} INFO - Running: ['***', 'tasks', 'run', 'age_check', 'age_check', 'scheduled__2022-08-11T00:00:00+00:00', '--job-id', '82', '--raw', '--subdir', 'DAGS_FOLDER/age.py', '--cfg-path', '/tmp/tmp3t6tp44t']
[2023-05-17T09:51:56.511+0000] {standard_task_runner.py:83} INFO - Job 82: Subtask age_check
[2023-05-17T09:51:56.679+0000] {task_command.py:388} INFO - Running <TaskInstance: age_check.age_check scheduled__2022-08-11T00:00:00+00:00 [running]> on host 242f95e3e8a8
[2023-05-17T09:51:56.834+0000] {taskinstance.py:1509} INFO - Exporting the following env vars:
AIRFLOW_CTX_DAG_OWNER=***
AIRFLOW_CTX_DAG_ID=age_check
AIRFLOW_CTX_TASK_ID=age_check
AIRFLOW_CTX_EXECUTION_DATE=2022-08-11T00:00:00+00:00
AIRFLOW_CTX_TRY_NUMBER=2
AIRFLOW_CTX_DAG_RUN_ID=scheduled__2022-08-11T00:00:00+00:00
[2023-05-17T09:51:56.849+0000] {taskinstance.py:1768} ERROR - Task failed with exception
Traceback (most recent call last):
  File "/home/airflow/.local/lib/python3.7/site-packages/airflow/operators/python.py", line 175, in execute
    return_value = self.execute_callable()
  File "/home/airflow/.local/lib/python3.7/site-packages/airflow/operators/python.py", line 192, in execute_callable
    return self.python_callable(*self.op_args, **self.op_kwargs)
  File "/opt/airflow/dags/age.py", line 35, in age_check
    birth_year = int(Variable.get('birth_year'))
  File "/home/airflow/.local/lib/python3.7/site-packages/airflow/models/variable.py", line 141, in get
    raise KeyError(f"Variable {key} does not exist")
KeyError: 'Variable birth_year does not exist'
[2023-05-17T09:51:56.867+0000] {taskinstance.py:1323} INFO - Marking task as UP_FOR_RETRY. dag_id=age_check, task_id=age_check, execution_date=20220811T000000, start_date=20230517T095156, end_date=20230517T095156
[2023-05-17T09:51:56.877+0000] {standard_task_runner.py:105} ERROR - Failed to execute job 82 for task age_check ('Variable birth_year does not exist'; 3962)
[2023-05-17T09:51:56.914+0000] {local_task_job.py:208} INFO - Task exited with return code 1
[2023-05-17T09:51:56.935+0000] {taskinstance.py:2578} INFO - 0 downstream tasks scheduled from follow-on schedule check
