[2023-04-28T01:51:31.548+0000] {taskinstance.py:1083} INFO - Dependencies all met for <TaskInstance: create_s3_bucket.create_bucket scheduled__2023-04-27T00:00:00+00:00 [queued]>
[2023-04-28T01:51:31.559+0000] {taskinstance.py:1083} INFO - Dependencies all met for <TaskInstance: create_s3_bucket.create_bucket scheduled__2023-04-27T00:00:00+00:00 [queued]>
[2023-04-28T01:51:31.560+0000] {taskinstance.py:1279} INFO - 
--------------------------------------------------------------------------------
[2023-04-28T01:51:31.563+0000] {taskinstance.py:1280} INFO - Starting attempt 3 of 4
[2023-04-28T01:51:31.564+0000] {taskinstance.py:1281} INFO - 
--------------------------------------------------------------------------------
[2023-04-28T01:51:31.578+0000] {taskinstance.py:1300} INFO - Executing <Task(PythonOperator): create_bucket> on 2023-04-27 00:00:00+00:00
[2023-04-28T01:51:31.585+0000] {standard_task_runner.py:55} INFO - Started process 65194 to run task
[2023-04-28T01:51:31.589+0000] {standard_task_runner.py:82} INFO - Running: ['***', 'tasks', 'run', 'create_s3_bucket', 'create_bucket', 'scheduled__2023-04-27T00:00:00+00:00', '--job-id', '4676', '--raw', '--subdir', 'DAGS_FOLDER/s3_create.py', '--cfg-path', '/tmp/tmp8dw1skv6']
[2023-04-28T01:51:31.591+0000] {standard_task_runner.py:83} INFO - Job 4676: Subtask create_bucket
[2023-04-28T01:51:31.662+0000] {task_command.py:388} INFO - Running <TaskInstance: create_s3_bucket.create_bucket scheduled__2023-04-27T00:00:00+00:00 [running]> on host fe34f61acbb3
[2023-04-28T01:51:31.739+0000] {taskinstance.py:1509} INFO - Exporting the following env vars:
AIRFLOW_CTX_DAG_OWNER=***
AIRFLOW_CTX_DAG_ID=create_s3_bucket
AIRFLOW_CTX_TASK_ID=create_bucket
AIRFLOW_CTX_EXECUTION_DATE=2023-04-27T00:00:00+00:00
AIRFLOW_CTX_TRY_NUMBER=3
AIRFLOW_CTX_DAG_RUN_ID=scheduled__2023-04-27T00:00:00+00:00
[2023-04-28T01:51:32.468+0000] {taskinstance.py:1768} ERROR - Task failed with exception
Traceback (most recent call last):
  File "/home/airflow/.local/lib/python3.7/site-packages/airflow/operators/python.py", line 175, in execute
    return_value = self.execute_callable()
  File "/home/airflow/.local/lib/python3.7/site-packages/airflow/operators/python.py", line 192, in execute_callable
    return self.python_callable(*self.op_args, **self.op_kwargs)
  File "/opt/airflow/dags/s3_create.py", line 33, in create_bucket
    'LocationConstraint': 'eu-central-1',
  File "/home/airflow/.local/lib/python3.7/site-packages/boto3/resources/factory.py", line 580, in do_action
    response = action(self, *args, **kwargs)
  File "/home/airflow/.local/lib/python3.7/site-packages/boto3/resources/action.py", line 88, in __call__
    response = getattr(parent.meta.client, operation_name)(*args, **params)
  File "/home/airflow/.local/lib/python3.7/site-packages/botocore/client.py", line 530, in _api_call
    return self._make_api_call(operation_name, kwargs)
  File "/home/airflow/.local/lib/python3.7/site-packages/botocore/client.py", line 960, in _make_api_call
    raise error_class(parsed_response, operation_name)
botocore.exceptions.ClientError: An error occurred (RequestTimeTooSkewed) when calling the CreateBucket operation: The difference between the request time and the current time is too large.
[2023-04-28T01:51:32.484+0000] {taskinstance.py:1323} INFO - Marking task as UP_FOR_RETRY. dag_id=create_s3_bucket, task_id=create_bucket, execution_date=20230427T000000, start_date=20230428T015131, end_date=20230428T015132
[2023-04-28T01:51:32.499+0000] {standard_task_runner.py:105} ERROR - Failed to execute job 4676 for task create_bucket (An error occurred (RequestTimeTooSkewed) when calling the CreateBucket operation: The difference between the request time and the current time is too large.; 65194)
[2023-04-28T01:51:32.534+0000] {local_task_job.py:208} INFO - Task exited with return code 1
[2023-04-28T01:51:32.548+0000] {taskinstance.py:2578} INFO - 0 downstream tasks scheduled from follow-on schedule check
