[2024-01-23T00:29:03.436+0000] {taskinstance.py:1157} INFO - Dependencies all met for dep_context=non-requeueable deps ti=<TaskInstance: read_s3_data.read_s3_data scheduled__2024-01-22T00:00:00+00:00 [queued]>
[2024-01-23T00:29:03.444+0000] {taskinstance.py:1157} INFO - Dependencies all met for dep_context=requeueable deps ti=<TaskInstance: read_s3_data.read_s3_data scheduled__2024-01-22T00:00:00+00:00 [queued]>
[2024-01-23T00:29:03.446+0000] {taskinstance.py:1359} INFO - Starting attempt 2 of 4
[2024-01-23T00:29:03.457+0000] {taskinstance.py:1380} INFO - Executing <Task(PythonOperator): read_s3_data> on 2024-01-22 00:00:00+00:00
[2024-01-23T00:29:03.465+0000] {standard_task_runner.py:57} INFO - Started process 21373 to run task
[2024-01-23T00:29:03.471+0000] {standard_task_runner.py:84} INFO - Running: ['***', 'tasks', 'run', 'read_s3_data', 'read_s3_data', 'scheduled__2024-01-22T00:00:00+00:00', '--job-id', '2684', '--raw', '--subdir', 'DAGS_FOLDER/read.py', '--cfg-path', '/tmp/tmpy6zemxgx']
[2024-01-23T00:29:03.475+0000] {standard_task_runner.py:85} INFO - Job 2684: Subtask read_s3_data
[2024-01-23T00:29:03.534+0000] {task_command.py:415} INFO - Running <TaskInstance: read_s3_data.read_s3_data scheduled__2024-01-22T00:00:00+00:00 [running]> on host dbb3489df186
[2024-01-23T00:29:03.594+0000] {taskinstance.py:1660} INFO - Exporting env vars: AIRFLOW_CTX_DAG_OWNER='***' AIRFLOW_CTX_DAG_ID='read_s3_data' AIRFLOW_CTX_TASK_ID='read_s3_data' AIRFLOW_CTX_EXECUTION_DATE='2024-01-22T00:00:00+00:00' AIRFLOW_CTX_TRY_NUMBER='2' AIRFLOW_CTX_DAG_RUN_ID='scheduled__2024-01-22T00:00:00+00:00'
[2024-01-23T00:29:04.120+0000] {taskinstance.py:1935} ERROR - Task failed with exception
Traceback (most recent call last):
  File "/home/airflow/.local/lib/python3.11/site-packages/airflow/operators/python.py", line 192, in execute
    return_value = self.execute_callable()
                   ^^^^^^^^^^^^^^^^^^^^^^^
  File "/home/airflow/.local/lib/python3.11/site-packages/airflow/operators/python.py", line 209, in execute_callable
    return self.python_callable(*self.op_args, **self.op_kwargs)
           ^^^^^^^^^^^^^^^^^^^^^^^^^^^^^^^^^^^^^^^^^^^^^^^^^^^^^
  File "/opt/airflow/dags/read.py", line 37, in read_s3_file
    df = wr.s3.read_csv(path='s3://staging-olist/customer/olist_customers_dataset.csv', boto3_session=session)
         ^^^^^^^^^^^^^^^^^^^^^^^^^^^^^^^^^^^^^^^^^^^^^^^^^^^^^^^^^^^^^^^^^^^^^^^^^^^^^^^^^^^^^^^^^^^^^^^^^^^^^
  File "/home/airflow/.local/lib/python3.11/site-packages/awswrangler/_utils.py", line 176, in inner
    return func(*args, **kwargs)
           ^^^^^^^^^^^^^^^^^^^^^
  File "/home/airflow/.local/lib/python3.11/site-packages/awswrangler/s3/_read_text.py", line 293, in read_csv
    return _read_text_format(
           ^^^^^^^^^^^^^^^^^^
  File "/home/airflow/.local/lib/python3.11/site-packages/awswrangler/s3/_read_text.py", line 93, in _read_text_format
    paths: List[str] = _path2list(
                       ^^^^^^^^^^^
  File "/home/airflow/.local/lib/python3.11/site-packages/awswrangler/s3/_list.py", line 35, in _path2list
    paths: List[str] = [
                       ^
  File "/home/airflow/.local/lib/python3.11/site-packages/awswrangler/s3/_list.py", line 35, in <listcomp>
    paths: List[str] = [
                       ^
  File "/home/airflow/.local/lib/python3.11/site-packages/awswrangler/s3/_list.py", line 146, in _list_objects_paginate
    for page in response_iterator:  # pylint: disable=too-many-nested-blocks
  File "/home/airflow/.local/lib/python3.11/site-packages/botocore/paginate.py", line 269, in __iter__
    response = self._make_request(current_kwargs)
               ^^^^^^^^^^^^^^^^^^^^^^^^^^^^^^^^^^
  File "/home/airflow/.local/lib/python3.11/site-packages/botocore/paginate.py", line 357, in _make_request
    return self._method(**current_kwargs)
           ^^^^^^^^^^^^^^^^^^^^^^^^^^^^^^
  File "/home/airflow/.local/lib/python3.11/site-packages/botocore/client.py", line 535, in _api_call
    return self._make_api_call(operation_name, kwargs)
           ^^^^^^^^^^^^^^^^^^^^^^^^^^^^^^^^^^^^^^^^^^^
  File "/home/airflow/.local/lib/python3.11/site-packages/botocore/client.py", line 980, in _make_api_call
    raise error_class(parsed_response, operation_name)
botocore.exceptions.ClientError: An error occurred (RequestTimeTooSkewed) when calling the ListObjectsV2 operation: The difference between the request time and the current time is too large.
[2024-01-23T00:29:04.134+0000] {taskinstance.py:1398} INFO - Marking task as UP_FOR_RETRY. dag_id=read_s3_data, task_id=read_s3_data, execution_date=20240122T000000, start_date=20240123T002903, end_date=20240123T002904
[2024-01-23T00:29:04.143+0000] {standard_task_runner.py:104} ERROR - Failed to execute job 2684 for task read_s3_data (An error occurred (RequestTimeTooSkewed) when calling the ListObjectsV2 operation: The difference between the request time and the current time is too large.; 21373)
[2024-01-23T00:29:04.190+0000] {local_task_job_runner.py:228} INFO - Task exited with return code 1
[2024-01-23T00:29:04.205+0000] {taskinstance.py:2776} INFO - 0 downstream tasks scheduled from follow-on schedule check
