[2023-12-17T21:18:22.069+0000] {taskinstance.py:1157} INFO - Dependencies all met for dep_context=non-requeueable deps ti=<TaskInstance: read_s3_data.read_s3_data scheduled__2023-08-02T00:00:00+00:00 [queued]>
[2023-12-17T21:18:22.124+0000] {taskinstance.py:1157} INFO - Dependencies all met for dep_context=requeueable deps ti=<TaskInstance: read_s3_data.read_s3_data scheduled__2023-08-02T00:00:00+00:00 [queued]>
[2023-12-17T21:18:22.134+0000] {taskinstance.py:1359} INFO - Starting attempt 4 of 4
[2023-12-17T21:18:22.192+0000] {taskinstance.py:1380} INFO - Executing <Task(PythonOperator): read_s3_data> on 2023-08-02 00:00:00+00:00
[2023-12-17T21:18:22.257+0000] {standard_task_runner.py:84} INFO - Running: ['***', 'tasks', 'run', 'read_s3_data', 'read_s3_data', 'scheduled__2023-08-02T00:00:00+00:00', '--job-id', '7722', '--raw', '--subdir', 'DAGS_FOLDER/read.py', '--cfg-path', '/tmp/tmprx_3m44s']
[2023-12-17T21:18:22.261+0000] {standard_task_runner.py:85} INFO - Job 7722: Subtask read_s3_data
[2023-12-17T21:18:22.256+0000] {standard_task_runner.py:57} INFO - Started process 1287 to run task
[2023-12-17T21:18:22.603+0000] {task_command.py:415} INFO - Running <TaskInstance: read_s3_data.read_s3_data scheduled__2023-08-02T00:00:00+00:00 [running]> on host 883df3d9b006
[2023-12-17T21:18:23.100+0000] {taskinstance.py:1660} INFO - Exporting env vars: AIRFLOW_CTX_DAG_OWNER='***' AIRFLOW_CTX_DAG_ID='read_s3_data' AIRFLOW_CTX_TASK_ID='read_s3_data' AIRFLOW_CTX_EXECUTION_DATE='2023-08-02T00:00:00+00:00' AIRFLOW_CTX_TRY_NUMBER='4' AIRFLOW_CTX_DAG_RUN_ID='scheduled__2023-08-02T00:00:00+00:00'
[2023-12-17T21:18:23.105+0000] {taskinstance.py:1935} ERROR - Task failed with exception
Traceback (most recent call last):
  File "/home/airflow/.local/lib/python3.11/site-packages/airflow/operators/python.py", line 192, in execute
    return_value = self.execute_callable()
                   ^^^^^^^^^^^^^^^^^^^^^^^
  File "/home/airflow/.local/lib/python3.11/site-packages/airflow/operators/python.py", line 209, in execute_callable
    return self.python_callable(*self.op_args, **self.op_kwargs)
           ^^^^^^^^^^^^^^^^^^^^^^^^^^^^^^^^^^^^^^^^^^^^^^^^^^^^^
TypeError: generic_s3_clients() missing 2 required positional arguments: 'ACCESS_KEY' and 'SECRET_KEY'
[2023-12-17T21:18:23.134+0000] {taskinstance.py:1398} INFO - Marking task as FAILED. dag_id=read_s3_data, task_id=read_s3_data, execution_date=20230802T000000, start_date=20231217T211822, end_date=20231217T211823
[2023-12-17T21:18:23.170+0000] {standard_task_runner.py:104} ERROR - Failed to execute job 7722 for task read_s3_data (generic_s3_clients() missing 2 required positional arguments: 'ACCESS_KEY' and 'SECRET_KEY'; 1287)
[2023-12-17T21:18:23.328+0000] {local_task_job_runner.py:228} INFO - Task exited with return code 1
[2023-12-17T21:18:23.477+0000] {taskinstance.py:2776} INFO - 0 downstream tasks scheduled from follow-on schedule check
[2024-01-20T15:49:45.814+0000] {taskinstance.py:1157} INFO - Dependencies all met for dep_context=non-requeueable deps ti=<TaskInstance: read_s3_data.read_s3_data scheduled__2023-08-02T00:00:00+00:00 [queued]>
[2024-01-20T15:49:45.842+0000] {taskinstance.py:1157} INFO - Dependencies all met for dep_context=requeueable deps ti=<TaskInstance: read_s3_data.read_s3_data scheduled__2023-08-02T00:00:00+00:00 [queued]>
[2024-01-20T15:49:45.850+0000] {taskinstance.py:1359} INFO - Starting attempt 4 of 4
[2024-01-20T15:49:45.878+0000] {taskinstance.py:1380} INFO - Executing <Task(PythonOperator): read_s3_data> on 2023-08-02 00:00:00+00:00
[2024-01-20T15:49:45.907+0000] {standard_task_runner.py:57} INFO - Started process 312 to run task
[2024-01-20T15:49:45.932+0000] {standard_task_runner.py:84} INFO - Running: ['***', 'tasks', 'run', 'read_s3_data', 'read_s3_data', 'scheduled__2023-08-02T00:00:00+00:00', '--job-id', '1920', '--raw', '--subdir', 'DAGS_FOLDER/read.py', '--cfg-path', '/tmp/tmpka2iaguj']
[2024-01-20T15:49:45.944+0000] {standard_task_runner.py:85} INFO - Job 1920: Subtask read_s3_data
[2024-01-20T15:49:46.118+0000] {task_command.py:415} INFO - Running <TaskInstance: read_s3_data.read_s3_data scheduled__2023-08-02T00:00:00+00:00 [running]> on host dbb3489df186
[2024-01-20T15:49:46.412+0000] {taskinstance.py:1660} INFO - Exporting env vars: AIRFLOW_CTX_DAG_OWNER='***' AIRFLOW_CTX_DAG_ID='read_s3_data' AIRFLOW_CTX_TASK_ID='read_s3_data' AIRFLOW_CTX_EXECUTION_DATE='2023-08-02T00:00:00+00:00' AIRFLOW_CTX_TRY_NUMBER='4' AIRFLOW_CTX_DAG_RUN_ID='scheduled__2023-08-02T00:00:00+00:00'
[2024-01-20T15:50:06.097+0000] {local_task_job_runner.py:294} WARNING - State of this instance has been externally set to failed. Terminating instance.
[2024-01-20T15:50:06.103+0000] {process_utils.py:131} INFO - Sending 15 to group 312. PIDs of all processes in the group: [312]
[2024-01-20T15:50:06.105+0000] {process_utils.py:86} INFO - Sending the signal 15 to group 312
[2024-01-20T15:50:06.109+0000] {taskinstance.py:1630} ERROR - Received SIGTERM. Terminating subprocesses.
[2024-01-20T15:50:06.202+0000] {process_utils.py:79} INFO - Process psutil.Process(pid=312, status='terminated', exitcode=0, started='15:49:45') (312) terminated with exit code 0
