[2023-12-17T15:31:58.049+0000] {taskinstance.py:1157} INFO - Dependencies all met for dep_context=non-requeueable deps ti=<TaskInstance: read_s3_data.read_s3_data scheduled__2022-10-29T00:00:00+00:00 [queued]>
[2023-12-17T15:31:58.084+0000] {taskinstance.py:1157} INFO - Dependencies all met for dep_context=requeueable deps ti=<TaskInstance: read_s3_data.read_s3_data scheduled__2022-10-29T00:00:00+00:00 [queued]>
[2023-12-17T15:31:58.087+0000] {taskinstance.py:1359} INFO - Starting attempt 1 of 4
[2023-12-17T15:31:58.247+0000] {taskinstance.py:1380} INFO - Executing <Task(PythonOperator): read_s3_data> on 2022-10-29 00:00:00+00:00
[2023-12-17T15:31:58.268+0000] {standard_task_runner.py:57} INFO - Started process 27128 to run task
[2023-12-17T15:31:58.286+0000] {standard_task_runner.py:84} INFO - Running: ['***', 'tasks', 'run', 'read_s3_data', 'read_s3_data', 'scheduled__2022-10-29T00:00:00+00:00', '--job-id', '6618', '--raw', '--subdir', 'DAGS_FOLDER/read.py', '--cfg-path', '/tmp/tmppxn89kaf']
[2023-12-17T15:31:58.293+0000] {standard_task_runner.py:85} INFO - Job 6618: Subtask read_s3_data
[2023-12-17T15:31:58.428+0000] {task_command.py:415} INFO - Running <TaskInstance: read_s3_data.read_s3_data scheduled__2022-10-29T00:00:00+00:00 [running]> on host 533efb53d454
[2023-12-17T15:31:58.588+0000] {taskinstance.py:1660} INFO - Exporting env vars: AIRFLOW_CTX_DAG_OWNER='***' AIRFLOW_CTX_DAG_ID='read_s3_data' AIRFLOW_CTX_TASK_ID='read_s3_data' AIRFLOW_CTX_EXECUTION_DATE='2022-10-29T00:00:00+00:00' AIRFLOW_CTX_TRY_NUMBER='1' AIRFLOW_CTX_DAG_RUN_ID='scheduled__2022-10-29T00:00:00+00:00'
[2023-12-17T15:31:58.593+0000] {taskinstance.py:1935} ERROR - Task failed with exception
Traceback (most recent call last):
  File "/home/airflow/.local/lib/python3.11/site-packages/airflow/operators/python.py", line 192, in execute
    return_value = self.execute_callable()
                   ^^^^^^^^^^^^^^^^^^^^^^^
  File "/home/airflow/.local/lib/python3.11/site-packages/airflow/operators/python.py", line 209, in execute_callable
    return self.python_callable(*self.op_args, **self.op_kwargs)
           ^^^^^^^^^^^^^^^^^^^^^^^^^^^^^^^^^^^^^^^^^^^^^^^^^^^^^
TypeError: generic_s3_clients() missing 2 required positional arguments: 'ACCESS_KEY' and 'SECRET_KEY'
[2023-12-17T15:31:58.608+0000] {taskinstance.py:1398} INFO - Marking task as UP_FOR_RETRY. dag_id=read_s3_data, task_id=read_s3_data, execution_date=20221029T000000, start_date=20231217T153158, end_date=20231217T153158
[2023-12-17T15:31:58.645+0000] {standard_task_runner.py:104} ERROR - Failed to execute job 6618 for task read_s3_data (generic_s3_clients() missing 2 required positional arguments: 'ACCESS_KEY' and 'SECRET_KEY'; 27128)
[2023-12-17T15:31:58.702+0000] {local_task_job_runner.py:228} INFO - Task exited with return code 1
[2023-12-17T15:31:58.733+0000] {taskinstance.py:2776} INFO - 0 downstream tasks scheduled from follow-on schedule check
[2023-12-24T17:10:56.306+0000] {taskinstance.py:1157} INFO - Dependencies all met for dep_context=non-requeueable deps ti=<TaskInstance: read_s3_data.read_s3_data scheduled__2022-10-29T00:00:00+00:00 [queued]>
[2023-12-24T17:10:56.315+0000] {taskinstance.py:1157} INFO - Dependencies all met for dep_context=requeueable deps ti=<TaskInstance: read_s3_data.read_s3_data scheduled__2022-10-29T00:00:00+00:00 [queued]>
[2023-12-24T17:10:56.317+0000] {taskinstance.py:1359} INFO - Starting attempt 1 of 4
[2023-12-24T17:10:56.330+0000] {taskinstance.py:1380} INFO - Executing <Task(PythonOperator): read_s3_data> on 2022-10-29 00:00:00+00:00
[2023-12-24T17:10:56.336+0000] {standard_task_runner.py:57} INFO - Started process 72 to run task
[2023-12-24T17:10:56.342+0000] {standard_task_runner.py:84} INFO - Running: ['***', 'tasks', 'run', 'read_s3_data', 'read_s3_data', 'scheduled__2022-10-29T00:00:00+00:00', '--job-id', '247', '--raw', '--subdir', 'DAGS_FOLDER/read.py', '--cfg-path', '/tmp/tmpmwiisuze']
[2023-12-24T17:10:56.344+0000] {standard_task_runner.py:85} INFO - Job 247: Subtask read_s3_data
[2023-12-24T17:10:56.399+0000] {task_command.py:415} INFO - Running <TaskInstance: read_s3_data.read_s3_data scheduled__2022-10-29T00:00:00+00:00 [running]> on host dbb3489df186
[2023-12-24T17:10:56.458+0000] {taskinstance.py:1660} INFO - Exporting env vars: AIRFLOW_CTX_DAG_OWNER='***' AIRFLOW_CTX_DAG_ID='read_s3_data' AIRFLOW_CTX_TASK_ID='read_s3_data' AIRFLOW_CTX_EXECUTION_DATE='2022-10-29T00:00:00+00:00' AIRFLOW_CTX_TRY_NUMBER='1' AIRFLOW_CTX_DAG_RUN_ID='scheduled__2022-10-29T00:00:00+00:00'
[2023-12-24T17:11:02.865+0000] {python.py:194} INFO - Done. Returned value was:                             customer_id  ... customer_state
0      06b8999e2fba1a1fbc88172c00ba8bc7  ...             SP
1      18955e83d337fd6b2def6b18a428ac77  ...             SP
2      4e7b3e00288586ebd08712fdd0374a03  ...             SP
3      b2b6027bc5c5109e529d4dc6358b12c3  ...             SP
4      4f2d8ab171c80ec8364f7c12e35b23ad  ...             SP
...                                 ...  ...            ...
99436  17ddf5dd5d51696bb3d7c6291687be6f  ...             SP
99437  e7b71a9017aa05c9a7fd292d714858e8  ...             SP
99438  5e28dfe12db7fb50a4b2f691faecea5e  ...             CE
99439  56b18e2166679b8a959d72dd06da27f9  ...             RS
99440  274fa6071e5e17fe303b9748641082c8  ...             SP

[99441 rows x 5 columns]
[2023-12-24T17:11:02.889+0000] {warnings.py:109} WARNING - /home/***/.local/lib/python3.11/site-packages/pyarrow/pandas_compat.py:373: FutureWarning: is_sparse is deprecated and will be removed in a future version. Check `isinstance(dtype, pd.SparseDtype)` instead.
  if _pandas_api.is_sparse(col):

[2023-12-24T17:11:04.070+0000] {taskinstance.py:1398} INFO - Marking task as SUCCESS. dag_id=read_s3_data, task_id=read_s3_data, execution_date=20221029T000000, start_date=20231224T171056, end_date=20231224T171104
[2023-12-24T17:11:04.345+0000] {local_task_job_runner.py:228} INFO - Task exited with return code 0
[2023-12-24T17:11:04.375+0000] {taskinstance.py:2776} INFO - 0 downstream tasks scheduled from follow-on schedule check
