[2024-02-03T22:31:09.618+0000] {taskinstance.py:1157} INFO - Dependencies all met for dep_context=non-requeueable deps ti=<TaskInstance: api_file-extract-and-upload.transfer_file scheduled__2022-10-20T00:00:00+00:00 [queued]>
[2024-02-03T22:31:09.770+0000] {taskinstance.py:1157} INFO - Dependencies all met for dep_context=requeueable deps ti=<TaskInstance: api_file-extract-and-upload.transfer_file scheduled__2022-10-20T00:00:00+00:00 [queued]>
[2024-02-03T22:31:09.782+0000] {taskinstance.py:1359} INFO - Starting attempt 3 of 4
[2024-02-03T22:31:09.984+0000] {taskinstance.py:1380} INFO - Executing <Task(PythonOperator): transfer_file> on 2022-10-20 00:00:00+00:00
[2024-02-03T22:31:10.117+0000] {standard_task_runner.py:57} INFO - Started process 9240 to run task
[2024-02-03T22:31:10.434+0000] {standard_task_runner.py:84} INFO - Running: ['***', 'tasks', 'run', 'api_file-extract-and-upload', 'transfer_file', 'scheduled__2022-10-20T00:00:00+00:00', '--job-id', '8023', '--raw', '--subdir', 'DAGS_FOLDER/api_extract.py', '--cfg-path', '/tmp/tmp28_s7h58']
[2024-02-03T22:31:10.481+0000] {standard_task_runner.py:85} INFO - Job 8023: Subtask transfer_file
[2024-02-03T22:31:11.857+0000] {task_command.py:415} INFO - Running <TaskInstance: api_file-extract-and-upload.transfer_file scheduled__2022-10-20T00:00:00+00:00 [running]> on host dbb3489df186
[2024-02-03T22:31:13.310+0000] {taskinstance.py:1660} INFO - Exporting env vars: AIRFLOW_CTX_DAG_OWNER='***' AIRFLOW_CTX_DAG_ID='api_file-extract-and-upload' AIRFLOW_CTX_TASK_ID='transfer_file' AIRFLOW_CTX_EXECUTION_DATE='2022-10-20T00:00:00+00:00' AIRFLOW_CTX_TRY_NUMBER='3' AIRFLOW_CTX_DAG_RUN_ID='scheduled__2022-10-20T00:00:00+00:00'
[2024-02-03T22:31:28.091+0000] {taskinstance.py:1935} ERROR - Task failed with exception
Traceback (most recent call last):
  File "/home/airflow/.local/lib/python3.11/site-packages/airflow/operators/python.py", line 192, in execute
    return_value = self.execute_callable()
                   ^^^^^^^^^^^^^^^^^^^^^^^
  File "/home/airflow/.local/lib/python3.11/site-packages/airflow/operators/python.py", line 209, in execute_callable
    return self.python_callable(*self.op_args, **self.op_kwargs)
           ^^^^^^^^^^^^^^^^^^^^^^^^^^^^^^^^^^^^^^^^^^^^^^^^^^^^^
  File "/opt/airflow/dags/api_extract.py", line 70, in transfer_file
    new_df = df.to_sql("old-uni-file", con=conn, schema="olist")
             ^^^^^^^^^^^^^^^^^^^^^^^^^^^^^^^^^^^^^^^^^^^^^^^^^^^
  File "/home/airflow/.local/lib/python3.11/site-packages/pandas/util/_decorators.py", line 333, in wrapper
    return func(*args, **kwargs)
           ^^^^^^^^^^^^^^^^^^^^^
  File "/home/airflow/.local/lib/python3.11/site-packages/pandas/core/generic.py", line 3008, in to_sql
    return sql.to_sql(
           ^^^^^^^^^^^
  File "/home/airflow/.local/lib/python3.11/site-packages/pandas/io/sql.py", line 788, in to_sql
    return pandas_sql.to_sql(
           ^^^^^^^^^^^^^^^^^^
  File "/home/airflow/.local/lib/python3.11/site-packages/pandas/io/sql.py", line 1948, in to_sql
    table = self.prep_table(
            ^^^^^^^^^^^^^^^^
  File "/home/airflow/.local/lib/python3.11/site-packages/pandas/io/sql.py", line 1852, in prep_table
    table.create()
  File "/home/airflow/.local/lib/python3.11/site-packages/pandas/io/sql.py", line 927, in create
    raise ValueError(f"Table '{self.name}' already exists.")
ValueError: Table 'old-uni-file' already exists.
[2024-02-03T22:31:28.790+0000] {taskinstance.py:1398} INFO - Marking task as UP_FOR_RETRY. dag_id=api_file-extract-and-upload, task_id=transfer_file, execution_date=20221020T000000, start_date=20240203T223109, end_date=20240203T223128
[2024-02-03T22:31:29.356+0000] {standard_task_runner.py:104} ERROR - Failed to execute job 8023 for task transfer_file (Table 'old-uni-file' already exists.; 9240)
[2024-02-03T22:31:29.954+0000] {local_task_job_runner.py:228} INFO - Task exited with return code 1
[2024-02-03T22:31:30.650+0000] {taskinstance.py:2776} INFO - 0 downstream tasks scheduled from follow-on schedule check
