[2023-12-17T19:32:50.213+0000] {taskinstance.py:1157} INFO - Dependencies all met for dep_context=non-requeueable deps ti=<TaskInstance: read_s3_data.read_s3_data scheduled__2023-03-12T00:00:00+00:00 [queued]>
[2023-12-17T19:32:52.084+0000] {taskinstance.py:1157} INFO - Dependencies all met for dep_context=requeueable deps ti=<TaskInstance: read_s3_data.read_s3_data scheduled__2023-03-12T00:00:00+00:00 [queued]>
[2023-12-17T19:32:52.100+0000] {taskinstance.py:1359} INFO - Starting attempt 4 of 4
[2023-12-17T19:32:54.463+0000] {taskinstance.py:1380} INFO - Executing <Task(PythonOperator): read_s3_data> on 2023-03-12 00:00:00+00:00
[2023-12-17T19:32:55.945+0000] {standard_task_runner.py:57} INFO - Started process 30827 to run task
[2023-12-17T19:32:57.015+0000] {standard_task_runner.py:84} INFO - Running: ['***', 'tasks', 'run', 'read_s3_data', 'read_s3_data', 'scheduled__2023-03-12T00:00:00+00:00', '--job-id', '7099', '--raw', '--subdir', 'DAGS_FOLDER/read.py', '--cfg-path', '/tmp/tmp8zd1_zj0']
[2023-12-17T19:32:57.178+0000] {standard_task_runner.py:85} INFO - Job 7099: Subtask read_s3_data
[2023-12-17T19:33:01.216+0000] {task_command.py:415} INFO - Running <TaskInstance: read_s3_data.read_s3_data scheduled__2023-03-12T00:00:00+00:00 [running]> on host 533efb53d454
[2023-12-17T19:33:04.369+0000] {taskinstance.py:1660} INFO - Exporting env vars: AIRFLOW_CTX_DAG_OWNER='***' AIRFLOW_CTX_DAG_ID='read_s3_data' AIRFLOW_CTX_TASK_ID='read_s3_data' AIRFLOW_CTX_EXECUTION_DATE='2023-03-12T00:00:00+00:00' AIRFLOW_CTX_TRY_NUMBER='4' AIRFLOW_CTX_DAG_RUN_ID='scheduled__2023-03-12T00:00:00+00:00'
[2023-12-17T19:33:04.496+0000] {taskinstance.py:1935} ERROR - Task failed with exception
Traceback (most recent call last):
  File "/home/airflow/.local/lib/python3.11/site-packages/airflow/operators/python.py", line 192, in execute
    return_value = self.execute_callable()
                   ^^^^^^^^^^^^^^^^^^^^^^^
  File "/home/airflow/.local/lib/python3.11/site-packages/airflow/operators/python.py", line 209, in execute_callable
    return self.python_callable(*self.op_args, **self.op_kwargs)
           ^^^^^^^^^^^^^^^^^^^^^^^^^^^^^^^^^^^^^^^^^^^^^^^^^^^^^
TypeError: generic_s3_clients() missing 2 required positional arguments: 'ACCESS_KEY' and 'SECRET_KEY'
[2023-12-17T19:33:05.345+0000] {taskinstance.py:1398} INFO - Marking task as FAILED. dag_id=read_s3_data, task_id=read_s3_data, execution_date=20230312T000000, start_date=20231217T193250, end_date=20231217T193305
[2023-12-17T19:33:05.579+0000] {standard_task_runner.py:104} ERROR - Failed to execute job 7099 for task read_s3_data (generic_s3_clients() missing 2 required positional arguments: 'ACCESS_KEY' and 'SECRET_KEY'; 30827)
[2023-12-17T19:33:06.256+0000] {local_task_job_runner.py:228} INFO - Task exited with return code 1
[2023-12-17T19:33:08.326+0000] {taskinstance.py:2776} INFO - 0 downstream tasks scheduled from follow-on schedule check
[2024-01-20T14:44:32.985+0000] {taskinstance.py:1157} INFO - Dependencies all met for dep_context=non-requeueable deps ti=<TaskInstance: read_s3_data.read_s3_data scheduled__2023-03-12T00:00:00+00:00 [queued]>
[2024-01-20T14:44:32.993+0000] {taskinstance.py:1157} INFO - Dependencies all met for dep_context=requeueable deps ti=<TaskInstance: read_s3_data.read_s3_data scheduled__2023-03-12T00:00:00+00:00 [queued]>
[2024-01-20T14:44:32.995+0000] {taskinstance.py:1359} INFO - Starting attempt 4 of 4
[2024-01-20T14:44:33.004+0000] {taskinstance.py:1380} INFO - Executing <Task(PythonOperator): read_s3_data> on 2023-03-12 00:00:00+00:00
[2024-01-20T14:44:33.009+0000] {standard_task_runner.py:57} INFO - Started process 62096 to run task
[2024-01-20T14:44:33.016+0000] {standard_task_runner.py:84} INFO - Running: ['***', 'tasks', 'run', 'read_s3_data', 'read_s3_data', 'scheduled__2023-03-12T00:00:00+00:00', '--job-id', '1318', '--raw', '--subdir', 'DAGS_FOLDER/read.py', '--cfg-path', '/tmp/tmp5qkaydac']
[2024-01-20T14:44:33.019+0000] {standard_task_runner.py:85} INFO - Job 1318: Subtask read_s3_data
[2024-01-20T14:44:33.070+0000] {task_command.py:415} INFO - Running <TaskInstance: read_s3_data.read_s3_data scheduled__2023-03-12T00:00:00+00:00 [running]> on host dbb3489df186
[2024-01-20T14:44:33.141+0000] {taskinstance.py:1660} INFO - Exporting env vars: AIRFLOW_CTX_DAG_OWNER='***' AIRFLOW_CTX_DAG_ID='read_s3_data' AIRFLOW_CTX_TASK_ID='read_s3_data' AIRFLOW_CTX_EXECUTION_DATE='2023-03-12T00:00:00+00:00' AIRFLOW_CTX_TRY_NUMBER='4' AIRFLOW_CTX_DAG_RUN_ID='scheduled__2023-03-12T00:00:00+00:00'
[2024-01-20T14:46:19.474+0000] {taskinstance.py:1935} ERROR - Task failed with exception
Traceback (most recent call last):
  File "/home/airflow/.local/lib/python3.11/site-packages/airflow/operators/python.py", line 192, in execute
    return_value = self.execute_callable()
                   ^^^^^^^^^^^^^^^^^^^^^^^
  File "/home/airflow/.local/lib/python3.11/site-packages/airflow/operators/python.py", line 209, in execute_callable
    return self.python_callable(*self.op_args, **self.op_kwargs)
           ^^^^^^^^^^^^^^^^^^^^^^^^^^^^^^^^^^^^^^^^^^^^^^^^^^^^^
  File "/opt/airflow/dags/read.py", line 40, in read_s3_file
    cnxn = create_engine("postgresql+psycopg2://staging_db:DnrbWdUcaZxyIc7v:5432/main")
           ^^^^^^^^^^^^^^^^^^^^^^^^^^^^^^^^^^^^^^^^^^^^^^^^^^^^^^^^^^^^^^^^^^^^^^^^^^^^
  File "<string>", line 2, in create_engine
  File "/home/airflow/.local/lib/python3.11/site-packages/sqlalchemy/util/deprecations.py", line 375, in warned
    return fn(*args, **kwargs)
           ^^^^^^^^^^^^^^^^^^^
  File "/home/airflow/.local/lib/python3.11/site-packages/sqlalchemy/engine/create.py", line 514, in create_engine
    u = _url.make_url(url)
        ^^^^^^^^^^^^^^^^^^
  File "/home/airflow/.local/lib/python3.11/site-packages/sqlalchemy/engine/url.py", line 738, in make_url
    return _parse_url(name_or_url)
           ^^^^^^^^^^^^^^^^^^^^^^^
  File "/home/airflow/.local/lib/python3.11/site-packages/sqlalchemy/engine/url.py", line 794, in _parse_url
    components["port"] = int(components["port"])
                         ^^^^^^^^^^^^^^^^^^^^^^^
ValueError: invalid literal for int() with base 10: 'DnrbWdUcaZxyIc7v:5432'
[2024-01-20T14:46:19.516+0000] {taskinstance.py:1398} INFO - Marking task as FAILED. dag_id=read_s3_data, task_id=read_s3_data, execution_date=20230312T000000, start_date=20240120T144432, end_date=20240120T144619
[2024-01-20T14:46:19.602+0000] {standard_task_runner.py:104} ERROR - Failed to execute job 1318 for task read_s3_data (invalid literal for int() with base 10: 'DnrbWdUcaZxyIc7v:5432'; 62096)
[2024-01-20T14:46:19.655+0000] {local_task_job_runner.py:228} INFO - Task exited with return code 1
[2024-01-20T14:46:19.711+0000] {taskinstance.py:2776} INFO - 0 downstream tasks scheduled from follow-on schedule check
