[2023-07-15T01:27:18.701+0000] {taskinstance.py:1083} INFO - Dependencies all met for <TaskInstance: age_check.age_check scheduled__2023-07-14T00:00:00+00:00 [queued]>
[2023-07-15T01:27:18.717+0000] {taskinstance.py:1083} INFO - Dependencies all met for <TaskInstance: age_check.age_check scheduled__2023-07-14T00:00:00+00:00 [queued]>
[2023-07-15T01:27:18.724+0000] {taskinstance.py:1279} INFO - 
--------------------------------------------------------------------------------
[2023-07-15T01:27:18.726+0000] {taskinstance.py:1280} INFO - Starting attempt 2 of 4
[2023-07-15T01:27:18.727+0000] {taskinstance.py:1281} INFO - 
--------------------------------------------------------------------------------
[2023-07-15T01:27:18.742+0000] {taskinstance.py:1300} INFO - Executing <Task(PythonOperator): age_check> on 2023-07-14 00:00:00+00:00
[2023-07-15T01:27:18.751+0000] {standard_task_runner.py:55} INFO - Started process 22463 to run task
[2023-07-15T01:27:18.763+0000] {standard_task_runner.py:82} INFO - Running: ['***', 'tasks', 'run', 'age_check', 'age_check', 'scheduled__2023-07-14T00:00:00+00:00', '--job-id', '3693', '--raw', '--subdir', 'DAGS_FOLDER/age.py', '--cfg-path', '/tmp/tmprzmv71qw']
[2023-07-15T01:27:18.765+0000] {standard_task_runner.py:83} INFO - Job 3693: Subtask age_check
[2023-07-15T01:27:18.854+0000] {task_command.py:388} INFO - Running <TaskInstance: age_check.age_check scheduled__2023-07-14T00:00:00+00:00 [running]> on host 25f6b46723d1
[2023-07-15T01:27:18.948+0000] {taskinstance.py:1509} INFO - Exporting the following env vars:
AIRFLOW_CTX_DAG_OWNER=***
AIRFLOW_CTX_DAG_ID=age_check
AIRFLOW_CTX_TASK_ID=age_check
AIRFLOW_CTX_EXECUTION_DATE=2023-07-14T00:00:00+00:00
AIRFLOW_CTX_TRY_NUMBER=2
AIRFLOW_CTX_DAG_RUN_ID=scheduled__2023-07-14T00:00:00+00:00
[2023-07-15T01:27:18.965+0000] {taskinstance.py:1768} ERROR - Task failed with exception
Traceback (most recent call last):
  File "/home/airflow/.local/lib/python3.7/site-packages/airflow/operators/python.py", line 175, in execute
    return_value = self.execute_callable()
  File "/home/airflow/.local/lib/python3.7/site-packages/airflow/operators/python.py", line 192, in execute_callable
    return self.python_callable(*self.op_args, **self.op_kwargs)
  File "/opt/airflow/dags/age.py", line 35, in age_check
    birth_year = int(Variable.get('birth_year'))
  File "/home/airflow/.local/lib/python3.7/site-packages/airflow/models/variable.py", line 141, in get
    raise KeyError(f"Variable {key} does not exist")
KeyError: 'Variable birth_year does not exist'
[2023-07-15T01:27:18.980+0000] {taskinstance.py:1323} INFO - Marking task as UP_FOR_RETRY. dag_id=age_check, task_id=age_check, execution_date=20230714T000000, start_date=20230715T012718, end_date=20230715T012718
[2023-07-15T01:27:19.008+0000] {standard_task_runner.py:105} ERROR - Failed to execute job 3693 for task age_check ('Variable birth_year does not exist'; 22463)
[2023-07-15T01:27:19.052+0000] {local_task_job.py:208} INFO - Task exited with return code 1
[2023-07-15T01:27:19.092+0000] {taskinstance.py:2578} INFO - 0 downstream tasks scheduled from follow-on schedule check
