[2023-10-26T02:11:27.493+0000] {taskinstance.py:1083} INFO - Dependencies all met for <TaskInstance: age_check.age_check scheduled__2023-10-25T00:00:00+00:00 [queued]>
[2023-10-26T02:11:27.500+0000] {taskinstance.py:1083} INFO - Dependencies all met for <TaskInstance: age_check.age_check scheduled__2023-10-25T00:00:00+00:00 [queued]>
[2023-10-26T02:11:27.501+0000] {taskinstance.py:1279} INFO - 
--------------------------------------------------------------------------------
[2023-10-26T02:11:27.502+0000] {taskinstance.py:1280} INFO - Starting attempt 4 of 4
[2023-10-26T02:11:27.503+0000] {taskinstance.py:1281} INFO - 
--------------------------------------------------------------------------------
[2023-10-26T02:11:27.512+0000] {taskinstance.py:1300} INFO - Executing <Task(PythonOperator): age_check> on 2023-10-25 00:00:00+00:00
[2023-10-26T02:11:27.520+0000] {standard_task_runner.py:55} INFO - Started process 114806 to run task
[2023-10-26T02:11:27.524+0000] {standard_task_runner.py:82} INFO - Running: ['***', 'tasks', 'run', 'age_check', 'age_check', 'scheduled__2023-10-25T00:00:00+00:00', '--job-id', '5282', '--raw', '--subdir', 'DAGS_FOLDER/age.py', '--cfg-path', '/tmp/tmpmtq8804w']
[2023-10-26T02:11:27.525+0000] {standard_task_runner.py:83} INFO - Job 5282: Subtask age_check
[2023-10-26T02:11:27.589+0000] {task_command.py:388} INFO - Running <TaskInstance: age_check.age_check scheduled__2023-10-25T00:00:00+00:00 [running]> on host 25f6b46723d1
[2023-10-26T02:11:27.641+0000] {taskinstance.py:1509} INFO - Exporting the following env vars:
AIRFLOW_CTX_DAG_OWNER=***
AIRFLOW_CTX_DAG_ID=age_check
AIRFLOW_CTX_TASK_ID=age_check
AIRFLOW_CTX_EXECUTION_DATE=2023-10-25T00:00:00+00:00
AIRFLOW_CTX_TRY_NUMBER=4
AIRFLOW_CTX_DAG_RUN_ID=scheduled__2023-10-25T00:00:00+00:00
[2023-10-26T02:11:27.649+0000] {taskinstance.py:1768} ERROR - Task failed with exception
Traceback (most recent call last):
  File "/home/airflow/.local/lib/python3.7/site-packages/airflow/operators/python.py", line 175, in execute
    return_value = self.execute_callable()
  File "/home/airflow/.local/lib/python3.7/site-packages/airflow/operators/python.py", line 192, in execute_callable
    return self.python_callable(*self.op_args, **self.op_kwargs)
  File "/opt/airflow/dags/age.py", line 35, in age_check
    birth_year = int(Variable.get('birth_year'))
  File "/home/airflow/.local/lib/python3.7/site-packages/airflow/models/variable.py", line 141, in get
    raise KeyError(f"Variable {key} does not exist")
KeyError: 'Variable birth_year does not exist'
[2023-10-26T02:11:27.660+0000] {taskinstance.py:1323} INFO - Marking task as FAILED. dag_id=age_check, task_id=age_check, execution_date=20231025T000000, start_date=20231026T021127, end_date=20231026T021127
[2023-10-26T02:11:27.669+0000] {standard_task_runner.py:105} ERROR - Failed to execute job 5282 for task age_check ('Variable birth_year does not exist'; 114806)
[2023-10-26T02:11:27.697+0000] {local_task_job.py:208} INFO - Task exited with return code 1
[2023-10-26T02:11:27.716+0000] {taskinstance.py:2578} INFO - 0 downstream tasks scheduled from follow-on schedule check
