[2023-04-19T12:39:10.756+0000] {taskinstance.py:1083} INFO - Dependencies all met for <TaskInstance: age_check.age_check scheduled__2022-09-21T00:00:00+00:00 [queued]>
[2023-04-19T12:39:10.840+0000] {taskinstance.py:1083} INFO - Dependencies all met for <TaskInstance: age_check.age_check scheduled__2022-09-21T00:00:00+00:00 [queued]>
[2023-04-19T12:39:10.844+0000] {taskinstance.py:1279} INFO - 
--------------------------------------------------------------------------------
[2023-04-19T12:39:10.845+0000] {taskinstance.py:1280} INFO - Starting attempt 2 of 4
[2023-04-19T12:39:10.847+0000] {taskinstance.py:1281} INFO - 
--------------------------------------------------------------------------------
[2023-04-19T12:39:10.916+0000] {taskinstance.py:1300} INFO - Executing <Task(PythonOperator): age_check> on 2022-09-21 00:00:00+00:00
[2023-04-19T12:39:10.945+0000] {standard_task_runner.py:55} INFO - Started process 22094 to run task
[2023-04-19T12:39:10.963+0000] {standard_task_runner.py:82} INFO - Running: ['***', 'tasks', 'run', 'age_check', 'age_check', 'scheduled__2022-09-21T00:00:00+00:00', '--job-id', '847', '--raw', '--subdir', 'DAGS_FOLDER/age.py', '--cfg-path', '/tmp/tmpmgvem8ge']
[2023-04-19T12:39:10.967+0000] {standard_task_runner.py:83} INFO - Job 847: Subtask age_check
[2023-04-19T12:39:11.125+0000] {task_command.py:388} INFO - Running <TaskInstance: age_check.age_check scheduled__2022-09-21T00:00:00+00:00 [running]> on host fe34f61acbb3
[2023-04-19T12:39:11.262+0000] {taskinstance.py:1509} INFO - Exporting the following env vars:
AIRFLOW_CTX_DAG_OWNER=***
AIRFLOW_CTX_DAG_ID=age_check
AIRFLOW_CTX_TASK_ID=age_check
AIRFLOW_CTX_EXECUTION_DATE=2022-09-21T00:00:00+00:00
AIRFLOW_CTX_TRY_NUMBER=2
AIRFLOW_CTX_DAG_RUN_ID=scheduled__2022-09-21T00:00:00+00:00
[2023-04-19T12:39:11.291+0000] {taskinstance.py:1768} ERROR - Task failed with exception
Traceback (most recent call last):
  File "/home/airflow/.local/lib/python3.7/site-packages/airflow/operators/python.py", line 175, in execute
    return_value = self.execute_callable()
  File "/home/airflow/.local/lib/python3.7/site-packages/airflow/operators/python.py", line 192, in execute_callable
    return self.python_callable(*self.op_args, **self.op_kwargs)
  File "/opt/airflow/dags/age.py", line 35, in age_check
    birth_year = int(Variable.get('birth_year'))
  File "/home/airflow/.local/lib/python3.7/site-packages/airflow/models/variable.py", line 141, in get
    raise KeyError(f"Variable {key} does not exist")
KeyError: 'Variable birth_year does not exist'
[2023-04-19T12:39:11.322+0000] {taskinstance.py:1323} INFO - Marking task as UP_FOR_RETRY. dag_id=age_check, task_id=age_check, execution_date=20220921T000000, start_date=20230419T123910, end_date=20230419T123911
[2023-04-19T12:39:11.357+0000] {standard_task_runner.py:105} ERROR - Failed to execute job 847 for task age_check ('Variable birth_year does not exist'; 22094)
[2023-04-19T12:39:11.388+0000] {local_task_job.py:208} INFO - Task exited with return code 1
[2023-04-19T12:39:11.446+0000] {taskinstance.py:2578} INFO - 0 downstream tasks scheduled from follow-on schedule check
[2023-05-17T09:54:50.786+0000] {taskinstance.py:1083} INFO - Dependencies all met for <TaskInstance: age_check.age_check scheduled__2022-09-21T00:00:00+00:00 [queued]>
[2023-05-17T09:54:50.794+0000] {taskinstance.py:1083} INFO - Dependencies all met for <TaskInstance: age_check.age_check scheduled__2022-09-21T00:00:00+00:00 [queued]>
[2023-05-17T09:54:50.795+0000] {taskinstance.py:1279} INFO - 
--------------------------------------------------------------------------------
[2023-05-17T09:54:50.797+0000] {taskinstance.py:1280} INFO - Starting attempt 2 of 4
[2023-05-17T09:54:50.798+0000] {taskinstance.py:1281} INFO - 
--------------------------------------------------------------------------------
[2023-05-17T09:54:50.812+0000] {taskinstance.py:1300} INFO - Executing <Task(PythonOperator): age_check> on 2022-09-21 00:00:00+00:00
[2023-05-17T09:54:50.827+0000] {standard_task_runner.py:55} INFO - Started process 4764 to run task
[2023-05-17T09:54:50.853+0000] {standard_task_runner.py:82} INFO - Running: ['***', 'tasks', 'run', 'age_check', 'age_check', 'scheduled__2022-09-21T00:00:00+00:00', '--job-id', '410', '--raw', '--subdir', 'DAGS_FOLDER/age.py', '--cfg-path', '/tmp/tmpei9854nu']
[2023-05-17T09:54:50.861+0000] {standard_task_runner.py:83} INFO - Job 410: Subtask age_check
[2023-05-17T09:54:50.952+0000] {task_command.py:388} INFO - Running <TaskInstance: age_check.age_check scheduled__2022-09-21T00:00:00+00:00 [running]> on host 242f95e3e8a8
[2023-05-17T09:54:51.037+0000] {taskinstance.py:1509} INFO - Exporting the following env vars:
AIRFLOW_CTX_DAG_OWNER=***
AIRFLOW_CTX_DAG_ID=age_check
AIRFLOW_CTX_TASK_ID=age_check
AIRFLOW_CTX_EXECUTION_DATE=2022-09-21T00:00:00+00:00
AIRFLOW_CTX_TRY_NUMBER=2
AIRFLOW_CTX_DAG_RUN_ID=scheduled__2022-09-21T00:00:00+00:00
[2023-05-17T09:54:51.068+0000] {taskinstance.py:1768} ERROR - Task failed with exception
Traceback (most recent call last):
  File "/home/airflow/.local/lib/python3.7/site-packages/airflow/operators/python.py", line 175, in execute
    return_value = self.execute_callable()
  File "/home/airflow/.local/lib/python3.7/site-packages/airflow/operators/python.py", line 192, in execute_callable
    return self.python_callable(*self.op_args, **self.op_kwargs)
  File "/opt/airflow/dags/age.py", line 35, in age_check
    birth_year = int(Variable.get('birth_year'))
  File "/home/airflow/.local/lib/python3.7/site-packages/airflow/models/variable.py", line 141, in get
    raise KeyError(f"Variable {key} does not exist")
KeyError: 'Variable birth_year does not exist'
[2023-05-17T09:54:51.085+0000] {taskinstance.py:1323} INFO - Marking task as UP_FOR_RETRY. dag_id=age_check, task_id=age_check, execution_date=20220921T000000, start_date=20230517T095450, end_date=20230517T095451
[2023-05-17T09:54:51.100+0000] {standard_task_runner.py:105} ERROR - Failed to execute job 410 for task age_check ('Variable birth_year does not exist'; 4764)
[2023-05-17T09:54:51.140+0000] {local_task_job.py:208} INFO - Task exited with return code 1
[2023-05-17T09:54:51.178+0000] {taskinstance.py:2578} INFO - 0 downstream tasks scheduled from follow-on schedule check
