[2023-04-26T02:10:47.726+0000] {taskinstance.py:1083} INFO - Dependencies all met for <TaskInstance: create_s3_bucket.create_bucket scheduled__2023-04-25T00:00:00+00:00 [queued]>
[2023-04-26T02:10:47.735+0000] {taskinstance.py:1083} INFO - Dependencies all met for <TaskInstance: create_s3_bucket.create_bucket scheduled__2023-04-25T00:00:00+00:00 [queued]>
[2023-04-26T02:10:47.737+0000] {taskinstance.py:1279} INFO - 
--------------------------------------------------------------------------------
[2023-04-26T02:10:47.738+0000] {taskinstance.py:1280} INFO - Starting attempt 4 of 4
[2023-04-26T02:10:47.739+0000] {taskinstance.py:1281} INFO - 
--------------------------------------------------------------------------------
[2023-04-26T02:10:47.752+0000] {taskinstance.py:1300} INFO - Executing <Task(PythonOperator): create_bucket> on 2023-04-25 00:00:00+00:00
[2023-04-26T02:10:47.759+0000] {standard_task_runner.py:55} INFO - Started process 44132 to run task
[2023-04-26T02:10:47.763+0000] {standard_task_runner.py:82} INFO - Running: ['***', 'tasks', 'run', 'create_s3_bucket', 'create_bucket', 'scheduled__2023-04-25T00:00:00+00:00', '--job-id', '4640', '--raw', '--subdir', 'DAGS_FOLDER/s3_create.py', '--cfg-path', '/tmp/tmpqgv_uzey']
[2023-04-26T02:10:47.764+0000] {standard_task_runner.py:83} INFO - Job 4640: Subtask create_bucket
[2023-04-26T02:10:47.833+0000] {task_command.py:388} INFO - Running <TaskInstance: create_s3_bucket.create_bucket scheduled__2023-04-25T00:00:00+00:00 [running]> on host fe34f61acbb3
[2023-04-26T02:10:47.938+0000] {taskinstance.py:1509} INFO - Exporting the following env vars:
AIRFLOW_CTX_DAG_OWNER=***
AIRFLOW_CTX_DAG_ID=create_s3_bucket
AIRFLOW_CTX_TASK_ID=create_bucket
AIRFLOW_CTX_EXECUTION_DATE=2023-04-25T00:00:00+00:00
AIRFLOW_CTX_TRY_NUMBER=4
AIRFLOW_CTX_DAG_RUN_ID=scheduled__2023-04-25T00:00:00+00:00
[2023-04-26T02:10:48.383+0000] {taskinstance.py:1768} ERROR - Task failed with exception
Traceback (most recent call last):
  File "/home/airflow/.local/lib/python3.7/site-packages/airflow/operators/python.py", line 175, in execute
    return_value = self.execute_callable()
  File "/home/airflow/.local/lib/python3.7/site-packages/airflow/operators/python.py", line 192, in execute_callable
    return self.python_callable(*self.op_args, **self.op_kwargs)
  File "/opt/airflow/dags/s3_create.py", line 33, in create_bucket
    'LocationConstraint': 'eu-central-1',
  File "/home/airflow/.local/lib/python3.7/site-packages/boto3/resources/factory.py", line 580, in do_action
    response = action(self, *args, **kwargs)
  File "/home/airflow/.local/lib/python3.7/site-packages/boto3/resources/action.py", line 88, in __call__
    response = getattr(parent.meta.client, operation_name)(*args, **params)
  File "/home/airflow/.local/lib/python3.7/site-packages/botocore/client.py", line 530, in _api_call
    return self._make_api_call(operation_name, kwargs)
  File "/home/airflow/.local/lib/python3.7/site-packages/botocore/client.py", line 960, in _make_api_call
    raise error_class(parsed_response, operation_name)
botocore.exceptions.ClientError: An error occurred (RequestTimeTooSkewed) when calling the CreateBucket operation: The difference between the request time and the current time is too large.
[2023-04-26T02:10:48.422+0000] {taskinstance.py:1323} INFO - Marking task as FAILED. dag_id=create_s3_bucket, task_id=create_bucket, execution_date=20230425T000000, start_date=20230426T021047, end_date=20230426T021048
[2023-04-26T02:10:48.431+0000] {standard_task_runner.py:105} ERROR - Failed to execute job 4640 for task create_bucket (An error occurred (RequestTimeTooSkewed) when calling the CreateBucket operation: The difference between the request time and the current time is too large.; 44132)
[2023-04-26T02:10:48.489+0000] {local_task_job.py:208} INFO - Task exited with return code 1
[2023-04-26T02:10:48.506+0000] {taskinstance.py:2578} INFO - 0 downstream tasks scheduled from follow-on schedule check
