[2023-04-19T12:38:06.409+0000] {taskinstance.py:1083} INFO - Dependencies all met for <TaskInstance: age_check.age_check scheduled__2022-08-31T00:00:00+00:00 [queued]>
[2023-04-19T12:38:06.424+0000] {taskinstance.py:1083} INFO - Dependencies all met for <TaskInstance: age_check.age_check scheduled__2022-08-31T00:00:00+00:00 [queued]>
[2023-04-19T12:38:06.429+0000] {taskinstance.py:1279} INFO - 
--------------------------------------------------------------------------------
[2023-04-19T12:38:06.431+0000] {taskinstance.py:1280} INFO - Starting attempt 2 of 4
[2023-04-19T12:38:06.432+0000] {taskinstance.py:1281} INFO - 
--------------------------------------------------------------------------------
[2023-04-19T12:38:06.454+0000] {taskinstance.py:1300} INFO - Executing <Task(PythonOperator): age_check> on 2022-08-31 00:00:00+00:00
[2023-04-19T12:38:06.462+0000] {standard_task_runner.py:55} INFO - Started process 21799 to run task
[2023-04-19T12:38:06.468+0000] {standard_task_runner.py:82} INFO - Running: ['***', 'tasks', 'run', 'age_check', 'age_check', 'scheduled__2022-08-31T00:00:00+00:00', '--job-id', '732', '--raw', '--subdir', 'DAGS_FOLDER/age.py', '--cfg-path', '/tmp/tmpojpb_3dn']
[2023-04-19T12:38:06.469+0000] {standard_task_runner.py:83} INFO - Job 732: Subtask age_check
[2023-04-19T12:38:06.557+0000] {task_command.py:388} INFO - Running <TaskInstance: age_check.age_check scheduled__2022-08-31T00:00:00+00:00 [running]> on host fe34f61acbb3
[2023-04-19T12:38:06.746+0000] {taskinstance.py:1509} INFO - Exporting the following env vars:
AIRFLOW_CTX_DAG_OWNER=***
AIRFLOW_CTX_DAG_ID=age_check
AIRFLOW_CTX_TASK_ID=age_check
AIRFLOW_CTX_EXECUTION_DATE=2022-08-31T00:00:00+00:00
AIRFLOW_CTX_TRY_NUMBER=2
AIRFLOW_CTX_DAG_RUN_ID=scheduled__2022-08-31T00:00:00+00:00
[2023-04-19T12:38:06.762+0000] {taskinstance.py:1768} ERROR - Task failed with exception
Traceback (most recent call last):
  File "/home/airflow/.local/lib/python3.7/site-packages/airflow/operators/python.py", line 175, in execute
    return_value = self.execute_callable()
  File "/home/airflow/.local/lib/python3.7/site-packages/airflow/operators/python.py", line 192, in execute_callable
    return self.python_callable(*self.op_args, **self.op_kwargs)
  File "/opt/airflow/dags/age.py", line 35, in age_check
    birth_year = int(Variable.get('birth_year'))
  File "/home/airflow/.local/lib/python3.7/site-packages/airflow/models/variable.py", line 141, in get
    raise KeyError(f"Variable {key} does not exist")
KeyError: 'Variable birth_year does not exist'
[2023-04-19T12:38:06.777+0000] {taskinstance.py:1323} INFO - Marking task as UP_FOR_RETRY. dag_id=age_check, task_id=age_check, execution_date=20220831T000000, start_date=20230419T123806, end_date=20230419T123806
[2023-04-19T12:38:06.812+0000] {standard_task_runner.py:105} ERROR - Failed to execute job 732 for task age_check ('Variable birth_year does not exist'; 21799)
[2023-04-19T12:38:06.848+0000] {local_task_job.py:208} INFO - Task exited with return code 1
[2023-04-19T12:38:07.227+0000] {taskinstance.py:2578} INFO - 0 downstream tasks scheduled from follow-on schedule check
[2023-05-17T09:53:51.456+0000] {taskinstance.py:1083} INFO - Dependencies all met for <TaskInstance: age_check.age_check scheduled__2022-08-31T00:00:00+00:00 [queued]>
[2023-05-17T09:53:51.463+0000] {taskinstance.py:1083} INFO - Dependencies all met for <TaskInstance: age_check.age_check scheduled__2022-08-31T00:00:00+00:00 [queued]>
[2023-05-17T09:53:51.464+0000] {taskinstance.py:1279} INFO - 
--------------------------------------------------------------------------------
[2023-05-17T09:53:51.465+0000] {taskinstance.py:1280} INFO - Starting attempt 2 of 4
[2023-05-17T09:53:51.466+0000] {taskinstance.py:1281} INFO - 
--------------------------------------------------------------------------------
[2023-05-17T09:53:51.476+0000] {taskinstance.py:1300} INFO - Executing <Task(PythonOperator): age_check> on 2022-08-31 00:00:00+00:00
[2023-05-17T09:53:51.481+0000] {standard_task_runner.py:55} INFO - Started process 4482 to run task
[2023-05-17T09:53:51.485+0000] {standard_task_runner.py:82} INFO - Running: ['***', 'tasks', 'run', 'age_check', 'age_check', 'scheduled__2022-08-31T00:00:00+00:00', '--job-id', '298', '--raw', '--subdir', 'DAGS_FOLDER/age.py', '--cfg-path', '/tmp/tmp6xtoa_ey']
[2023-05-17T09:53:51.487+0000] {standard_task_runner.py:83} INFO - Job 298: Subtask age_check
[2023-05-17T09:53:51.548+0000] {task_command.py:388} INFO - Running <TaskInstance: age_check.age_check scheduled__2022-08-31T00:00:00+00:00 [running]> on host 242f95e3e8a8
[2023-05-17T09:53:51.598+0000] {taskinstance.py:1509} INFO - Exporting the following env vars:
AIRFLOW_CTX_DAG_OWNER=***
AIRFLOW_CTX_DAG_ID=age_check
AIRFLOW_CTX_TASK_ID=age_check
AIRFLOW_CTX_EXECUTION_DATE=2022-08-31T00:00:00+00:00
AIRFLOW_CTX_TRY_NUMBER=2
AIRFLOW_CTX_DAG_RUN_ID=scheduled__2022-08-31T00:00:00+00:00
[2023-05-17T09:53:51.607+0000] {taskinstance.py:1768} ERROR - Task failed with exception
Traceback (most recent call last):
  File "/home/airflow/.local/lib/python3.7/site-packages/airflow/operators/python.py", line 175, in execute
    return_value = self.execute_callable()
  File "/home/airflow/.local/lib/python3.7/site-packages/airflow/operators/python.py", line 192, in execute_callable
    return self.python_callable(*self.op_args, **self.op_kwargs)
  File "/opt/airflow/dags/age.py", line 35, in age_check
    birth_year = int(Variable.get('birth_year'))
  File "/home/airflow/.local/lib/python3.7/site-packages/airflow/models/variable.py", line 141, in get
    raise KeyError(f"Variable {key} does not exist")
KeyError: 'Variable birth_year does not exist'
[2023-05-17T09:53:51.617+0000] {taskinstance.py:1323} INFO - Marking task as UP_FOR_RETRY. dag_id=age_check, task_id=age_check, execution_date=20220831T000000, start_date=20230517T095351, end_date=20230517T095351
[2023-05-17T09:53:51.626+0000] {standard_task_runner.py:105} ERROR - Failed to execute job 298 for task age_check ('Variable birth_year does not exist'; 4482)
[2023-05-17T09:53:51.657+0000] {local_task_job.py:208} INFO - Task exited with return code 1
[2023-05-17T09:53:51.677+0000] {taskinstance.py:2578} INFO - 0 downstream tasks scheduled from follow-on schedule check
