[2024-02-03T20:12:12.683+0000] {taskinstance.py:1157} INFO - Dependencies all met for dep_context=non-requeueable deps ti=<TaskInstance: read_s3_data112.read_s3_data scheduled__2022-11-01T00:00:00+00:00 [queued]>
[2024-02-03T20:12:12.748+0000] {taskinstance.py:1157} INFO - Dependencies all met for dep_context=requeueable deps ti=<TaskInstance: read_s3_data112.read_s3_data scheduled__2022-11-01T00:00:00+00:00 [queued]>
[2024-02-03T20:12:12.764+0000] {taskinstance.py:1359} INFO - Starting attempt 4 of 4
[2024-02-03T20:12:12.868+0000] {taskinstance.py:1380} INFO - Executing <Task(PythonOperator): read_s3_data> on 2022-11-01 00:00:00+00:00
[2024-02-03T20:12:13.133+0000] {standard_task_runner.py:57} INFO - Started process 7446 to run task
[2024-02-03T20:12:13.221+0000] {standard_task_runner.py:84} INFO - Running: ['***', 'tasks', 'run', 'read_s3_data112', 'read_s3_data', 'scheduled__2022-11-01T00:00:00+00:00', '--job-id', '5585', '--raw', '--subdir', 'DAGS_FOLDER/read.py', '--cfg-path', '/tmp/tmpxhd9smju']
[2024-02-03T20:12:13.269+0000] {standard_task_runner.py:85} INFO - Job 5585: Subtask read_s3_data
[2024-02-03T20:12:13.628+0000] {task_command.py:415} INFO - Running <TaskInstance: read_s3_data112.read_s3_data scheduled__2022-11-01T00:00:00+00:00 [running]> on host dbb3489df186
[2024-02-03T20:12:14.112+0000] {taskinstance.py:1660} INFO - Exporting env vars: AIRFLOW_CTX_DAG_OWNER='***' AIRFLOW_CTX_DAG_ID='read_s3_data112' AIRFLOW_CTX_TASK_ID='read_s3_data' AIRFLOW_CTX_EXECUTION_DATE='2022-11-01T00:00:00+00:00' AIRFLOW_CTX_TRY_NUMBER='4' AIRFLOW_CTX_DAG_RUN_ID='scheduled__2022-11-01T00:00:00+00:00'
[2024-02-03T20:12:40.285+0000] {taskinstance.py:1935} ERROR - Task failed with exception
Traceback (most recent call last):
  File "/home/airflow/.local/lib/python3.11/site-packages/airflow/operators/python.py", line 192, in execute
    return_value = self.execute_callable()
                   ^^^^^^^^^^^^^^^^^^^^^^^
  File "/home/airflow/.local/lib/python3.11/site-packages/airflow/operators/python.py", line 209, in execute_callable
    return self.python_callable(*self.op_args, **self.op_kwargs)
           ^^^^^^^^^^^^^^^^^^^^^^^^^^^^^^^^^^^^^^^^^^^^^^^^^^^^^
  File "/opt/airflow/dags/read.py", line 41, in read_s3_file
    new_df = df.to_sql("old_customer200", con=conn, schema="olist")
             ^^^^^^^^^^^^^^^^^^^^^^^^^^^^^^^^^^^^^^^^^^^^^^^^^^^^^^
  File "/home/airflow/.local/lib/python3.11/site-packages/pandas/util/_decorators.py", line 333, in wrapper
    return func(*args, **kwargs)
           ^^^^^^^^^^^^^^^^^^^^^
  File "/home/airflow/.local/lib/python3.11/site-packages/pandas/core/generic.py", line 3008, in to_sql
    return sql.to_sql(
           ^^^^^^^^^^^
  File "/home/airflow/.local/lib/python3.11/site-packages/pandas/io/sql.py", line 788, in to_sql
    return pandas_sql.to_sql(
           ^^^^^^^^^^^^^^^^^^
  File "/home/airflow/.local/lib/python3.11/site-packages/pandas/io/sql.py", line 1948, in to_sql
    table = self.prep_table(
            ^^^^^^^^^^^^^^^^
  File "/home/airflow/.local/lib/python3.11/site-packages/pandas/io/sql.py", line 1852, in prep_table
    table.create()
  File "/home/airflow/.local/lib/python3.11/site-packages/pandas/io/sql.py", line 927, in create
    raise ValueError(f"Table '{self.name}' already exists.")
ValueError: Table 'old_customer200' already exists.
[2024-02-03T20:12:42.122+0000] {taskinstance.py:1398} INFO - Marking task as FAILED. dag_id=read_s3_data112, task_id=read_s3_data, execution_date=20221101T000000, start_date=20240203T201212, end_date=20240203T201241
[2024-02-03T20:12:42.465+0000] {standard_task_runner.py:104} ERROR - Failed to execute job 5585 for task read_s3_data (Table 'old_customer200' already exists.; 7446)
[2024-02-03T20:12:42.669+0000] {local_task_job_runner.py:228} INFO - Task exited with return code 1
[2024-02-03T20:12:43.367+0000] {taskinstance.py:2776} INFO - 0 downstream tasks scheduled from follow-on schedule check
