[2023-12-17T15:27:25.496+0000] {taskinstance.py:1157} INFO - Dependencies all met for dep_context=non-requeueable deps ti=<TaskInstance: read_s3_data.read_s3_data scheduled__2022-09-18T00:00:00+00:00 [queued]>
[2023-12-17T15:27:25.606+0000] {taskinstance.py:1157} INFO - Dependencies all met for dep_context=requeueable deps ti=<TaskInstance: read_s3_data.read_s3_data scheduled__2022-09-18T00:00:00+00:00 [queued]>
[2023-12-17T15:27:25.632+0000] {taskinstance.py:1359} INFO - Starting attempt 2 of 4
[2023-12-17T15:27:25.967+0000] {taskinstance.py:1380} INFO - Executing <Task(PythonOperator): read_s3_data> on 2022-09-18 00:00:00+00:00
[2023-12-17T15:27:26.220+0000] {standard_task_runner.py:57} INFO - Started process 26575 to run task
[2023-12-17T15:27:26.390+0000] {standard_task_runner.py:84} INFO - Running: ['***', 'tasks', 'run', 'read_s3_data', 'read_s3_data', 'scheduled__2022-09-18T00:00:00+00:00', '--job-id', '6501', '--raw', '--subdir', 'DAGS_FOLDER/read.py', '--cfg-path', '/tmp/tmpahlqy6k6']
[2023-12-17T15:27:26.425+0000] {standard_task_runner.py:85} INFO - Job 6501: Subtask read_s3_data
[2023-12-17T15:27:27.102+0000] {task_command.py:415} INFO - Running <TaskInstance: read_s3_data.read_s3_data scheduled__2022-09-18T00:00:00+00:00 [running]> on host 533efb53d454
[2023-12-17T15:27:28.178+0000] {taskinstance.py:1660} INFO - Exporting env vars: AIRFLOW_CTX_DAG_OWNER='***' AIRFLOW_CTX_DAG_ID='read_s3_data' AIRFLOW_CTX_TASK_ID='read_s3_data' AIRFLOW_CTX_EXECUTION_DATE='2022-09-18T00:00:00+00:00' AIRFLOW_CTX_TRY_NUMBER='2' AIRFLOW_CTX_DAG_RUN_ID='scheduled__2022-09-18T00:00:00+00:00'
[2023-12-17T15:27:28.222+0000] {taskinstance.py:1935} ERROR - Task failed with exception
Traceback (most recent call last):
  File "/home/airflow/.local/lib/python3.11/site-packages/airflow/operators/python.py", line 192, in execute
    return_value = self.execute_callable()
                   ^^^^^^^^^^^^^^^^^^^^^^^
  File "/home/airflow/.local/lib/python3.11/site-packages/airflow/operators/python.py", line 209, in execute_callable
    return self.python_callable(*self.op_args, **self.op_kwargs)
           ^^^^^^^^^^^^^^^^^^^^^^^^^^^^^^^^^^^^^^^^^^^^^^^^^^^^^
TypeError: generic_s3_clients() missing 2 required positional arguments: 'ACCESS_KEY' and 'SECRET_KEY'
[2023-12-17T15:27:28.280+0000] {taskinstance.py:1398} INFO - Marking task as UP_FOR_RETRY. dag_id=read_s3_data, task_id=read_s3_data, execution_date=20220918T000000, start_date=20231217T152725, end_date=20231217T152728
[2023-12-17T15:27:28.437+0000] {standard_task_runner.py:104} ERROR - Failed to execute job 6501 for task read_s3_data (generic_s3_clients() missing 2 required positional arguments: 'ACCESS_KEY' and 'SECRET_KEY'; 26575)
[2023-12-17T15:27:28.815+0000] {local_task_job_runner.py:228} INFO - Task exited with return code 1
[2023-12-17T15:27:29.043+0000] {taskinstance.py:2776} INFO - 0 downstream tasks scheduled from follow-on schedule check
