[2023-12-17T15:46:53.772+0000] {taskinstance.py:1157} INFO - Dependencies all met for dep_context=non-requeueable deps ti=<TaskInstance: read_s3_data.read_s3_data scheduled__2022-12-30T00:00:00+00:00 [queued]>
[2023-12-17T15:46:53.831+0000] {taskinstance.py:1157} INFO - Dependencies all met for dep_context=requeueable deps ti=<TaskInstance: read_s3_data.read_s3_data scheduled__2022-12-30T00:00:00+00:00 [queued]>
[2023-12-17T15:46:53.833+0000] {taskinstance.py:1359} INFO - Starting attempt 3 of 4
[2023-12-17T15:46:53.913+0000] {taskinstance.py:1380} INFO - Executing <Task(PythonOperator): read_s3_data> on 2022-12-30 00:00:00+00:00
[2023-12-17T15:46:53.979+0000] {standard_task_runner.py:57} INFO - Started process 28537 to run task
[2023-12-17T15:46:54.029+0000] {standard_task_runner.py:84} INFO - Running: ['***', 'tasks', 'run', 'read_s3_data', 'read_s3_data', 'scheduled__2022-12-30T00:00:00+00:00', '--job-id', '6895', '--raw', '--subdir', 'DAGS_FOLDER/read.py', '--cfg-path', '/tmp/tmp97olsil8']
[2023-12-17T15:46:54.045+0000] {standard_task_runner.py:85} INFO - Job 6895: Subtask read_s3_data
[2023-12-17T15:46:54.427+0000] {task_command.py:415} INFO - Running <TaskInstance: read_s3_data.read_s3_data scheduled__2022-12-30T00:00:00+00:00 [running]> on host 533efb53d454
[2023-12-17T15:46:55.438+0000] {taskinstance.py:1660} INFO - Exporting env vars: AIRFLOW_CTX_DAG_OWNER='***' AIRFLOW_CTX_DAG_ID='read_s3_data' AIRFLOW_CTX_TASK_ID='read_s3_data' AIRFLOW_CTX_EXECUTION_DATE='2022-12-30T00:00:00+00:00' AIRFLOW_CTX_TRY_NUMBER='3' AIRFLOW_CTX_DAG_RUN_ID='scheduled__2022-12-30T00:00:00+00:00'
[2023-12-17T15:46:55.490+0000] {taskinstance.py:1935} ERROR - Task failed with exception
Traceback (most recent call last):
  File "/home/airflow/.local/lib/python3.11/site-packages/airflow/operators/python.py", line 192, in execute
    return_value = self.execute_callable()
                   ^^^^^^^^^^^^^^^^^^^^^^^
  File "/home/airflow/.local/lib/python3.11/site-packages/airflow/operators/python.py", line 209, in execute_callable
    return self.python_callable(*self.op_args, **self.op_kwargs)
           ^^^^^^^^^^^^^^^^^^^^^^^^^^^^^^^^^^^^^^^^^^^^^^^^^^^^^
TypeError: generic_s3_clients() missing 2 required positional arguments: 'ACCESS_KEY' and 'SECRET_KEY'
[2023-12-17T15:46:55.552+0000] {taskinstance.py:1398} INFO - Marking task as UP_FOR_RETRY. dag_id=read_s3_data, task_id=read_s3_data, execution_date=20221230T000000, start_date=20231217T154653, end_date=20231217T154655
[2023-12-17T15:46:55.641+0000] {standard_task_runner.py:104} ERROR - Failed to execute job 6895 for task read_s3_data (generic_s3_clients() missing 2 required positional arguments: 'ACCESS_KEY' and 'SECRET_KEY'; 28537)
[2023-12-17T15:46:55.888+0000] {local_task_job_runner.py:228} INFO - Task exited with return code 1
[2023-12-17T15:46:56.009+0000] {taskinstance.py:2776} INFO - 0 downstream tasks scheduled from follow-on schedule check
