[2023-08-19T02:06:27.022+0000] {taskinstance.py:1083} INFO - Dependencies all met for <TaskInstance: age_check.age_check scheduled__2023-08-18T00:00:00+00:00 [queued]>
[2023-08-19T02:06:27.041+0000] {taskinstance.py:1083} INFO - Dependencies all met for <TaskInstance: age_check.age_check scheduled__2023-08-18T00:00:00+00:00 [queued]>
[2023-08-19T02:06:27.042+0000] {taskinstance.py:1279} INFO - 
--------------------------------------------------------------------------------
[2023-08-19T02:06:27.044+0000] {taskinstance.py:1280} INFO - Starting attempt 1 of 4
[2023-08-19T02:06:27.045+0000] {taskinstance.py:1281} INFO - 
--------------------------------------------------------------------------------
[2023-08-19T02:06:27.064+0000] {taskinstance.py:1300} INFO - Executing <Task(PythonOperator): age_check> on 2023-08-18 00:00:00+00:00
[2023-08-19T02:06:27.073+0000] {standard_task_runner.py:55} INFO - Started process 67472 to run task
[2023-08-19T02:06:27.080+0000] {standard_task_runner.py:82} INFO - Running: ['***', 'tasks', 'run', 'age_check', 'age_check', 'scheduled__2023-08-18T00:00:00+00:00', '--job-id', '4130', '--raw', '--subdir', 'DAGS_FOLDER/age.py', '--cfg-path', '/tmp/tmphpfh68n3']
[2023-08-19T02:06:27.082+0000] {standard_task_runner.py:83} INFO - Job 4130: Subtask age_check
[2023-08-19T02:06:27.208+0000] {task_command.py:388} INFO - Running <TaskInstance: age_check.age_check scheduled__2023-08-18T00:00:00+00:00 [running]> on host 25f6b46723d1
[2023-08-19T02:06:27.346+0000] {taskinstance.py:1509} INFO - Exporting the following env vars:
AIRFLOW_CTX_DAG_OWNER=***
AIRFLOW_CTX_DAG_ID=age_check
AIRFLOW_CTX_TASK_ID=age_check
AIRFLOW_CTX_EXECUTION_DATE=2023-08-18T00:00:00+00:00
AIRFLOW_CTX_TRY_NUMBER=1
AIRFLOW_CTX_DAG_RUN_ID=scheduled__2023-08-18T00:00:00+00:00
[2023-08-19T02:06:27.375+0000] {taskinstance.py:1768} ERROR - Task failed with exception
Traceback (most recent call last):
  File "/home/airflow/.local/lib/python3.7/site-packages/airflow/operators/python.py", line 175, in execute
    return_value = self.execute_callable()
  File "/home/airflow/.local/lib/python3.7/site-packages/airflow/operators/python.py", line 192, in execute_callable
    return self.python_callable(*self.op_args, **self.op_kwargs)
  File "/opt/airflow/dags/age.py", line 35, in age_check
    birth_year = int(Variable.get('birth_year'))
  File "/home/airflow/.local/lib/python3.7/site-packages/airflow/models/variable.py", line 141, in get
    raise KeyError(f"Variable {key} does not exist")
KeyError: 'Variable birth_year does not exist'
[2023-08-19T02:06:27.402+0000] {taskinstance.py:1323} INFO - Marking task as UP_FOR_RETRY. dag_id=age_check, task_id=age_check, execution_date=20230818T000000, start_date=20230819T020627, end_date=20230819T020627
[2023-08-19T02:06:27.447+0000] {standard_task_runner.py:105} ERROR - Failed to execute job 4130 for task age_check ('Variable birth_year does not exist'; 67472)
[2023-08-19T02:06:27.465+0000] {local_task_job.py:208} INFO - Task exited with return code 1
[2023-08-19T02:06:27.506+0000] {taskinstance.py:2578} INFO - 0 downstream tasks scheduled from follow-on schedule check
