[2023-11-13T16:25:54.849+0000] {taskinstance.py:1083} INFO - Dependencies all met for <TaskInstance: read_s3_file.read_s3_file scheduled__2023-11-12T16:20:36.384064+00:00 [queued]>
[2023-11-13T16:25:54.857+0000] {taskinstance.py:1083} INFO - Dependencies all met for <TaskInstance: read_s3_file.read_s3_file scheduled__2023-11-12T16:20:36.384064+00:00 [queued]>
[2023-11-13T16:25:54.858+0000] {taskinstance.py:1279} INFO - 
--------------------------------------------------------------------------------
[2023-11-13T16:25:54.859+0000] {taskinstance.py:1280} INFO - Starting attempt 3 of 4
[2023-11-13T16:25:54.860+0000] {taskinstance.py:1281} INFO - 
--------------------------------------------------------------------------------
[2023-11-13T16:25:54.868+0000] {taskinstance.py:1300} INFO - Executing <Task(PythonOperator): read_s3_file> on 2023-11-12 16:20:36.384064+00:00
[2023-11-13T16:25:54.874+0000] {standard_task_runner.py:55} INFO - Started process 101503 to run task
[2023-11-13T16:25:54.877+0000] {standard_task_runner.py:82} INFO - Running: ['***', 'tasks', 'run', 'read_s3_file', 'read_s3_file', 'scheduled__2023-11-12T16:20:36.384064+00:00', '--job-id', '5630', '--raw', '--subdir', 'DAGS_FOLDER/desmond.py', '--cfg-path', '/tmp/tmpjhq4orve']
[2023-11-13T16:25:54.879+0000] {standard_task_runner.py:83} INFO - Job 5630: Subtask read_s3_file
[2023-11-13T16:25:54.939+0000] {task_command.py:388} INFO - Running <TaskInstance: read_s3_file.read_s3_file scheduled__2023-11-12T16:20:36.384064+00:00 [running]> on host 25f6b46723d1
[2023-11-13T16:25:55.000+0000] {taskinstance.py:1509} INFO - Exporting the following env vars:
AIRFLOW_CTX_DAG_OWNER=***
AIRFLOW_CTX_DAG_ID=read_s3_file
AIRFLOW_CTX_TASK_ID=read_s3_file
AIRFLOW_CTX_EXECUTION_DATE=2023-11-12T16:20:36.384064+00:00
AIRFLOW_CTX_TRY_NUMBER=3
AIRFLOW_CTX_DAG_RUN_ID=scheduled__2023-11-12T16:20:36.384064+00:00
[2023-11-13T16:25:55.002+0000] {taskinstance.py:1768} ERROR - Task failed with exception
Traceback (most recent call last):
  File "/home/airflow/.local/lib/python3.7/site-packages/airflow/operators/python.py", line 175, in execute
    return_value = self.execute_callable()
  File "/home/airflow/.local/lib/python3.7/site-packages/airflow/operators/python.py", line 192, in execute_callable
    return self.python_callable(*self.op_args, **self.op_kwargs)
TypeError: generic_s3_client() missing 2 required positional arguments: 'ACCESS_KEY' and 'SECRET_KEY'
[2023-11-13T16:25:55.013+0000] {taskinstance.py:1323} INFO - Marking task as UP_FOR_RETRY. dag_id=read_s3_file, task_id=read_s3_file, execution_date=20231112T162036, start_date=20231113T162554, end_date=20231113T162555
[2023-11-13T16:25:55.021+0000] {standard_task_runner.py:105} ERROR - Failed to execute job 5630 for task read_s3_file (generic_s3_client() missing 2 required positional arguments: 'ACCESS_KEY' and 'SECRET_KEY'; 101503)
[2023-11-13T16:25:55.051+0000] {local_task_job.py:208} INFO - Task exited with return code 1
[2023-11-13T16:25:55.070+0000] {taskinstance.py:2578} INFO - 0 downstream tasks scheduled from follow-on schedule check
