[2024-01-20T17:14:19.185+0000] {taskinstance.py:1157} INFO - Dependencies all met for dep_context=non-requeueable deps ti=<TaskInstance: read_s3_data.read_s3_data scheduled__2024-01-11T00:00:00+00:00 [queued]>
[2024-01-20T17:14:19.196+0000] {taskinstance.py:1157} INFO - Dependencies all met for dep_context=requeueable deps ti=<TaskInstance: read_s3_data.read_s3_data scheduled__2024-01-11T00:00:00+00:00 [queued]>
[2024-01-20T17:14:19.198+0000] {taskinstance.py:1359} INFO - Starting attempt 2 of 4
[2024-01-20T17:14:19.209+0000] {taskinstance.py:1380} INFO - Executing <Task(PythonOperator): read_s3_data> on 2024-01-11 00:00:00+00:00
[2024-01-20T17:14:19.218+0000] {standard_task_runner.py:57} INFO - Started process 4701 to run task
[2024-01-20T17:14:19.223+0000] {standard_task_runner.py:84} INFO - Running: ['***', 'tasks', 'run', 'read_s3_data', 'read_s3_data', 'scheduled__2024-01-11T00:00:00+00:00', '--job-id', '2591', '--raw', '--subdir', 'DAGS_FOLDER/read.py', '--cfg-path', '/tmp/tmpjv3e3kek']
[2024-01-20T17:14:19.227+0000] {standard_task_runner.py:85} INFO - Job 2591: Subtask read_s3_data
[2024-01-20T17:14:19.296+0000] {task_command.py:415} INFO - Running <TaskInstance: read_s3_data.read_s3_data scheduled__2024-01-11T00:00:00+00:00 [running]> on host dbb3489df186
[2024-01-20T17:14:19.375+0000] {taskinstance.py:1660} INFO - Exporting env vars: AIRFLOW_CTX_DAG_OWNER='***' AIRFLOW_CTX_DAG_ID='read_s3_data' AIRFLOW_CTX_TASK_ID='read_s3_data' AIRFLOW_CTX_EXECUTION_DATE='2024-01-11T00:00:00+00:00' AIRFLOW_CTX_TRY_NUMBER='2' AIRFLOW_CTX_DAG_RUN_ID='scheduled__2024-01-11T00:00:00+00:00'
[2024-01-20T17:15:59.021+0000] {taskinstance.py:1935} ERROR - Task failed with exception
Traceback (most recent call last):
  File "/home/airflow/.local/lib/python3.11/site-packages/airflow/operators/python.py", line 192, in execute
    return_value = self.execute_callable()
                   ^^^^^^^^^^^^^^^^^^^^^^^
  File "/home/airflow/.local/lib/python3.11/site-packages/airflow/operators/python.py", line 209, in execute_callable
    return self.python_callable(*self.op_args, **self.op_kwargs)
           ^^^^^^^^^^^^^^^^^^^^^^^^^^^^^^^^^^^^^^^^^^^^^^^^^^^^^
  File "/opt/airflow/dags/read.py", line 40, in read_s3_file
    conn = create_engine("postgresql+psycopg2://staging_db:DnrbWdUcaZxyIc7v@postgres.cnelwn14hnqh.eu-central-1.rds.amazonaws.com:port/main")
           ^^^^^^^^^^^^^^^^^^^^^^^^^^^^^^^^^^^^^^^^^^^^^^^^^^^^^^^^^^^^^^^^^^^^^^^^^^^^^^^^^^^^^^^^^^^^^^^^^^^^^^^^^^^^^^^^^^^^^^^^^^^^^^^^^
  File "<string>", line 2, in create_engine
  File "/home/airflow/.local/lib/python3.11/site-packages/sqlalchemy/util/deprecations.py", line 375, in warned
    return fn(*args, **kwargs)
           ^^^^^^^^^^^^^^^^^^^
  File "/home/airflow/.local/lib/python3.11/site-packages/sqlalchemy/engine/create.py", line 514, in create_engine
    u = _url.make_url(url)
        ^^^^^^^^^^^^^^^^^^
  File "/home/airflow/.local/lib/python3.11/site-packages/sqlalchemy/engine/url.py", line 738, in make_url
    return _parse_url(name_or_url)
           ^^^^^^^^^^^^^^^^^^^^^^^
  File "/home/airflow/.local/lib/python3.11/site-packages/sqlalchemy/engine/url.py", line 794, in _parse_url
    components["port"] = int(components["port"])
                         ^^^^^^^^^^^^^^^^^^^^^^^
ValueError: invalid literal for int() with base 10: 'port'
[2024-01-20T17:15:59.046+0000] {taskinstance.py:1398} INFO - Marking task as UP_FOR_RETRY. dag_id=read_s3_data, task_id=read_s3_data, execution_date=20240111T000000, start_date=20240120T171419, end_date=20240120T171559
[2024-01-20T17:15:59.070+0000] {standard_task_runner.py:104} ERROR - Failed to execute job 2591 for task read_s3_data (invalid literal for int() with base 10: 'port'; 4701)
[2024-01-20T17:15:59.119+0000] {local_task_job_runner.py:228} INFO - Task exited with return code 1
[2024-01-20T17:15:59.147+0000] {taskinstance.py:2776} INFO - 0 downstream tasks scheduled from follow-on schedule check
