[2023-04-27T01:20:39.464+0000] {taskinstance.py:1083} INFO - Dependencies all met for <TaskInstance: s3_keys.list_keys scheduled__2023-04-26T00:00:00+00:00 [queued]>
[2023-04-27T01:20:39.507+0000] {taskinstance.py:1083} INFO - Dependencies all met for <TaskInstance: s3_keys.list_keys scheduled__2023-04-26T00:00:00+00:00 [queued]>
[2023-04-27T01:20:39.508+0000] {taskinstance.py:1279} INFO - 
--------------------------------------------------------------------------------
[2023-04-27T01:20:39.509+0000] {taskinstance.py:1280} INFO - Starting attempt 1 of 1
[2023-04-27T01:20:39.510+0000] {taskinstance.py:1281} INFO - 
--------------------------------------------------------------------------------
[2023-04-27T01:20:39.604+0000] {taskinstance.py:1300} INFO - Executing <Task(PythonOperator): list_keys> on 2023-04-26 00:00:00+00:00
[2023-04-27T01:20:39.656+0000] {standard_task_runner.py:55} INFO - Started process 49886 to run task
[2023-04-27T01:20:39.680+0000] {standard_task_runner.py:82} INFO - Running: ['***', 'tasks', 'run', 's3_keys', 'list_keys', 'scheduled__2023-04-26T00:00:00+00:00', '--job-id', '4647', '--raw', '--subdir', 'DAGS_FOLDER/acess.py', '--cfg-path', '/tmp/tmp2ib5cwa5']
[2023-04-27T01:20:39.684+0000] {standard_task_runner.py:83} INFO - Job 4647: Subtask list_keys
[2023-04-27T01:20:39.915+0000] {task_command.py:388} INFO - Running <TaskInstance: s3_keys.list_keys scheduled__2023-04-26T00:00:00+00:00 [running]> on host fe34f61acbb3
[2023-04-27T01:20:40.566+0000] {taskinstance.py:1509} INFO - Exporting the following env vars:
AIRFLOW_CTX_DAG_OWNER=***
AIRFLOW_CTX_DAG_ID=s3_keys
AIRFLOW_CTX_TASK_ID=list_keys
AIRFLOW_CTX_EXECUTION_DATE=2023-04-26T00:00:00+00:00
AIRFLOW_CTX_TRY_NUMBER=1
AIRFLOW_CTX_DAG_RUN_ID=scheduled__2023-04-26T00:00:00+00:00
[2023-04-27T01:20:40.632+0000] {acess.py:12} INFO - Listing Keys from project-data-pipelines
[2023-04-27T01:20:40.808+0000] {base.py:73} INFO - Using connection ID 'aws_credentials' for task execution.
[2023-04-27T01:20:40.815+0000] {connection_wrapper.py:334} INFO - AWS Connection (conn_id='aws_credentials', conn_type='aws') credentials retrieved from login and password.
[2023-04-27T01:20:54.514+0000] {taskinstance.py:1768} ERROR - Task failed with exception
Traceback (most recent call last):
  File "/home/airflow/.local/lib/python3.7/site-packages/airflow/operators/python.py", line 175, in execute
    return_value = self.execute_callable()
  File "/home/airflow/.local/lib/python3.7/site-packages/airflow/operators/python.py", line 192, in execute_callable
    return self.python_callable(*self.op_args, **self.op_kwargs)
  File "/opt/airflow/dags/acess.py", line 13, in list_keys
    keys = hook.list_keys(bucket)
  File "/home/airflow/.local/lib/python3.7/site-packages/airflow/providers/amazon/aws/hooks/s3.py", line 70, in wrapper
    return func(*bound_args.args, **bound_args.kwargs)
  File "/home/airflow/.local/lib/python3.7/site-packages/airflow/providers/amazon/aws/hooks/s3.py", line 414, in list_keys
    for page in response:
  File "/home/airflow/.local/lib/python3.7/site-packages/botocore/paginate.py", line 269, in __iter__
    response = self._make_request(current_kwargs)
  File "/home/airflow/.local/lib/python3.7/site-packages/botocore/paginate.py", line 357, in _make_request
    return self._method(**current_kwargs)
  File "/home/airflow/.local/lib/python3.7/site-packages/botocore/client.py", line 530, in _api_call
    return self._make_api_call(operation_name, kwargs)
  File "/home/airflow/.local/lib/python3.7/site-packages/botocore/client.py", line 960, in _make_api_call
    raise error_class(parsed_response, operation_name)
botocore.exceptions.ClientError: An error occurred (RequestTimeTooSkewed) when calling the ListObjectsV2 operation: The difference between the request time and the current time is too large.
[2023-04-27T01:20:54.537+0000] {taskinstance.py:1323} INFO - Marking task as FAILED. dag_id=s3_keys, task_id=list_keys, execution_date=20230426T000000, start_date=20230427T012039, end_date=20230427T012054
[2023-04-27T01:20:54.576+0000] {standard_task_runner.py:105} ERROR - Failed to execute job 4647 for task list_keys (An error occurred (RequestTimeTooSkewed) when calling the ListObjectsV2 operation: The difference between the request time and the current time is too large.; 49886)
[2023-04-27T01:20:54.676+0000] {local_task_job.py:208} INFO - Task exited with return code 1
[2023-04-27T01:20:54.732+0000] {taskinstance.py:2578} INFO - 0 downstream tasks scheduled from follow-on schedule check
