[2023-10-10T18:43:20.928+0000] {taskinstance.py:1083} INFO - Dependencies all met for <TaskInstance: read_s3_file.read_s3_file scheduled__2023-10-09T16:20:36.384064+00:00 [queued]>
[2023-10-10T18:43:20.935+0000] {taskinstance.py:1083} INFO - Dependencies all met for <TaskInstance: read_s3_file.read_s3_file scheduled__2023-10-09T16:20:36.384064+00:00 [queued]>
[2023-10-10T18:43:20.935+0000] {taskinstance.py:1279} INFO - 
--------------------------------------------------------------------------------
[2023-10-10T18:43:20.936+0000] {taskinstance.py:1280} INFO - Starting attempt 4 of 4
[2023-10-10T18:43:20.938+0000] {taskinstance.py:1281} INFO - 
--------------------------------------------------------------------------------
[2023-10-10T18:43:20.946+0000] {taskinstance.py:1300} INFO - Executing <Task(PythonOperator): read_s3_file> on 2023-10-09 16:20:36.384064+00:00
[2023-10-10T18:43:20.950+0000] {standard_task_runner.py:55} INFO - Started process 78051 to run task
[2023-10-10T18:43:20.954+0000] {standard_task_runner.py:82} INFO - Running: ['***', 'tasks', 'run', 'read_s3_file', 'read_s3_file', 'scheduled__2023-10-09T16:20:36.384064+00:00', '--job-id', '5012', '--raw', '--subdir', 'DAGS_FOLDER/desmond.py', '--cfg-path', '/tmp/tmp7jof3r1r']
[2023-10-10T18:43:20.955+0000] {standard_task_runner.py:83} INFO - Job 5012: Subtask read_s3_file
[2023-10-10T18:43:21.011+0000] {task_command.py:388} INFO - Running <TaskInstance: read_s3_file.read_s3_file scheduled__2023-10-09T16:20:36.384064+00:00 [running]> on host 25f6b46723d1
[2023-10-10T18:43:21.060+0000] {taskinstance.py:1509} INFO - Exporting the following env vars:
AIRFLOW_CTX_DAG_OWNER=***
AIRFLOW_CTX_DAG_ID=read_s3_file
AIRFLOW_CTX_TASK_ID=read_s3_file
AIRFLOW_CTX_EXECUTION_DATE=2023-10-09T16:20:36.384064+00:00
AIRFLOW_CTX_TRY_NUMBER=4
AIRFLOW_CTX_DAG_RUN_ID=scheduled__2023-10-09T16:20:36.384064+00:00
[2023-10-10T18:43:21.063+0000] {taskinstance.py:1768} ERROR - Task failed with exception
Traceback (most recent call last):
  File "/home/airflow/.local/lib/python3.7/site-packages/airflow/operators/python.py", line 175, in execute
    return_value = self.execute_callable()
  File "/home/airflow/.local/lib/python3.7/site-packages/airflow/operators/python.py", line 192, in execute_callable
    return self.python_callable(*self.op_args, **self.op_kwargs)
TypeError: generic_s3_client() missing 2 required positional arguments: 'ACCESS_KEY' and 'SECRET_KEY'
[2023-10-10T18:43:21.071+0000] {taskinstance.py:1323} INFO - Marking task as FAILED. dag_id=read_s3_file, task_id=read_s3_file, execution_date=20231009T162036, start_date=20231010T184320, end_date=20231010T184321
[2023-10-10T18:43:21.079+0000] {standard_task_runner.py:105} ERROR - Failed to execute job 5012 for task read_s3_file (generic_s3_client() missing 2 required positional arguments: 'ACCESS_KEY' and 'SECRET_KEY'; 78051)
[2023-10-10T18:43:21.125+0000] {local_task_job.py:208} INFO - Task exited with return code 1
[2023-10-10T18:43:21.150+0000] {taskinstance.py:2578} INFO - 0 downstream tasks scheduled from follow-on schedule check
