[2024-01-20T16:33:36.311+0000] {taskinstance.py:1157} INFO - Dependencies all met for dep_context=non-requeueable deps ti=<TaskInstance: read_s3_data.read_s3_data scheduled__2023-10-27T00:00:00+00:00 [queued]>
[2024-01-20T16:33:36.326+0000] {taskinstance.py:1157} INFO - Dependencies all met for dep_context=requeueable deps ti=<TaskInstance: read_s3_data.read_s3_data scheduled__2023-10-27T00:00:00+00:00 [queued]>
[2024-01-20T16:33:36.336+0000] {taskinstance.py:1359} INFO - Starting attempt 2 of 4
[2024-01-20T16:33:36.357+0000] {taskinstance.py:1380} INFO - Executing <Task(PythonOperator): read_s3_data> on 2023-10-27 00:00:00+00:00
[2024-01-20T16:33:36.369+0000] {standard_task_runner.py:57} INFO - Started process 2374 to run task
[2024-01-20T16:33:36.375+0000] {standard_task_runner.py:84} INFO - Running: ['***', 'tasks', 'run', 'read_s3_data', 'read_s3_data', 'scheduled__2023-10-27T00:00:00+00:00', '--job-id', '2230', '--raw', '--subdir', 'DAGS_FOLDER/read.py', '--cfg-path', '/tmp/tmp35y9xdcw']
[2024-01-20T16:33:36.380+0000] {standard_task_runner.py:85} INFO - Job 2230: Subtask read_s3_data
[2024-01-20T16:33:36.465+0000] {task_command.py:415} INFO - Running <TaskInstance: read_s3_data.read_s3_data scheduled__2023-10-27T00:00:00+00:00 [running]> on host dbb3489df186
[2024-01-20T16:33:36.541+0000] {taskinstance.py:1660} INFO - Exporting env vars: AIRFLOW_CTX_DAG_OWNER='***' AIRFLOW_CTX_DAG_ID='read_s3_data' AIRFLOW_CTX_TASK_ID='read_s3_data' AIRFLOW_CTX_EXECUTION_DATE='2023-10-27T00:00:00+00:00' AIRFLOW_CTX_TRY_NUMBER='2' AIRFLOW_CTX_DAG_RUN_ID='scheduled__2023-10-27T00:00:00+00:00'
[2024-01-20T16:35:16.370+0000] {taskinstance.py:1935} ERROR - Task failed with exception
Traceback (most recent call last):
  File "/home/airflow/.local/lib/python3.11/site-packages/airflow/operators/python.py", line 192, in execute
    return_value = self.execute_callable()
                   ^^^^^^^^^^^^^^^^^^^^^^^
  File "/home/airflow/.local/lib/python3.11/site-packages/airflow/operators/python.py", line 209, in execute_callable
    return self.python_callable(*self.op_args, **self.op_kwargs)
           ^^^^^^^^^^^^^^^^^^^^^^^^^^^^^^^^^^^^^^^^^^^^^^^^^^^^^
  File "/opt/airflow/dags/read.py", line 41, in read_s3_file
    df.to_sql("olist.customer", con=conn, schema="olist")
  File "/home/airflow/.local/lib/python3.11/site-packages/pandas/util/_decorators.py", line 333, in wrapper
    return func(*args, **kwargs)
           ^^^^^^^^^^^^^^^^^^^^^
  File "/home/airflow/.local/lib/python3.11/site-packages/pandas/core/generic.py", line 3008, in to_sql
    return sql.to_sql(
           ^^^^^^^^^^^
  File "/home/airflow/.local/lib/python3.11/site-packages/pandas/io/sql.py", line 788, in to_sql
    return pandas_sql.to_sql(
           ^^^^^^^^^^^^^^^^^^
  File "/home/airflow/.local/lib/python3.11/site-packages/pandas/io/sql.py", line 1948, in to_sql
    table = self.prep_table(
            ^^^^^^^^^^^^^^^^
  File "/home/airflow/.local/lib/python3.11/site-packages/pandas/io/sql.py", line 1852, in prep_table
    table.create()
  File "/home/airflow/.local/lib/python3.11/site-packages/pandas/io/sql.py", line 927, in create
    raise ValueError(f"Table '{self.name}' already exists.")
ValueError: Table 'olist.customer' already exists.
[2024-01-20T16:35:16.394+0000] {taskinstance.py:1398} INFO - Marking task as UP_FOR_RETRY. dag_id=read_s3_data, task_id=read_s3_data, execution_date=20231027T000000, start_date=20240120T163336, end_date=20240120T163516
[2024-01-20T16:35:16.414+0000] {standard_task_runner.py:104} ERROR - Failed to execute job 2230 for task read_s3_data (Table 'olist.customer' already exists.; 2374)
[2024-01-20T16:35:16.457+0000] {local_task_job_runner.py:228} INFO - Task exited with return code 1
[2024-01-20T16:35:16.484+0000] {taskinstance.py:2776} INFO - 0 downstream tasks scheduled from follow-on schedule check
