[2024-02-03T21:28:39.479+0000] {taskinstance.py:1157} INFO - Dependencies all met for dep_context=non-requeueable deps ti=<TaskInstance: read_s3_data112.read_s3_data scheduled__2023-03-02T00:00:00+00:00 [queued]>
[2024-02-03T21:28:39.645+0000] {taskinstance.py:1157} INFO - Dependencies all met for dep_context=requeueable deps ti=<TaskInstance: read_s3_data112.read_s3_data scheduled__2023-03-02T00:00:00+00:00 [queued]>
[2024-02-03T21:28:39.664+0000] {taskinstance.py:1359} INFO - Starting attempt 2 of 4
[2024-02-03T21:28:39.853+0000] {taskinstance.py:1380} INFO - Executing <Task(PythonOperator): read_s3_data> on 2023-03-02 00:00:00+00:00
[2024-02-03T21:28:40.719+0000] {standard_task_runner.py:57} INFO - Started process 4530 to run task
[2024-02-03T21:28:40.764+0000] {standard_task_runner.py:84} INFO - Running: ['***', 'tasks', 'run', 'read_s3_data112', 'read_s3_data', 'scheduled__2023-03-02T00:00:00+00:00', '--job-id', '7188', '--raw', '--subdir', 'DAGS_FOLDER/read.py', '--cfg-path', '/tmp/tmp9rh122nz']
[2024-02-03T21:28:40.801+0000] {standard_task_runner.py:85} INFO - Job 7188: Subtask read_s3_data
[2024-02-03T21:28:41.709+0000] {task_command.py:415} INFO - Running <TaskInstance: read_s3_data112.read_s3_data scheduled__2023-03-02T00:00:00+00:00 [running]> on host dbb3489df186
[2024-02-03T21:28:42.554+0000] {taskinstance.py:1660} INFO - Exporting env vars: AIRFLOW_CTX_DAG_OWNER='***' AIRFLOW_CTX_DAG_ID='read_s3_data112' AIRFLOW_CTX_TASK_ID='read_s3_data' AIRFLOW_CTX_EXECUTION_DATE='2023-03-02T00:00:00+00:00' AIRFLOW_CTX_TRY_NUMBER='2' AIRFLOW_CTX_DAG_RUN_ID='scheduled__2023-03-02T00:00:00+00:00'
[2024-02-03T21:29:23.201+0000] {taskinstance.py:1935} ERROR - Task failed with exception
Traceback (most recent call last):
  File "/home/airflow/.local/lib/python3.11/site-packages/airflow/operators/python.py", line 192, in execute
    return_value = self.execute_callable()
                   ^^^^^^^^^^^^^^^^^^^^^^^
  File "/home/airflow/.local/lib/python3.11/site-packages/airflow/operators/python.py", line 209, in execute_callable
    return self.python_callable(*self.op_args, **self.op_kwargs)
           ^^^^^^^^^^^^^^^^^^^^^^^^^^^^^^^^^^^^^^^^^^^^^^^^^^^^^
  File "/opt/airflow/dags/read.py", line 41, in read_s3_file
    new_df = df.to_sql("old_customer200", con=conn, schema="olist")
             ^^^^^^^^^^^^^^^^^^^^^^^^^^^^^^^^^^^^^^^^^^^^^^^^^^^^^^
  File "/home/airflow/.local/lib/python3.11/site-packages/pandas/util/_decorators.py", line 333, in wrapper
    return func(*args, **kwargs)
           ^^^^^^^^^^^^^^^^^^^^^
  File "/home/airflow/.local/lib/python3.11/site-packages/pandas/core/generic.py", line 3008, in to_sql
    return sql.to_sql(
           ^^^^^^^^^^^
  File "/home/airflow/.local/lib/python3.11/site-packages/pandas/io/sql.py", line 788, in to_sql
    return pandas_sql.to_sql(
           ^^^^^^^^^^^^^^^^^^
  File "/home/airflow/.local/lib/python3.11/site-packages/pandas/io/sql.py", line 1948, in to_sql
    table = self.prep_table(
            ^^^^^^^^^^^^^^^^
  File "/home/airflow/.local/lib/python3.11/site-packages/pandas/io/sql.py", line 1852, in prep_table
    table.create()
  File "/home/airflow/.local/lib/python3.11/site-packages/pandas/io/sql.py", line 927, in create
    raise ValueError(f"Table '{self.name}' already exists.")
ValueError: Table 'old_customer200' already exists.
[2024-02-03T21:29:24.520+0000] {taskinstance.py:1398} INFO - Marking task as UP_FOR_RETRY. dag_id=read_s3_data112, task_id=read_s3_data, execution_date=20230302T000000, start_date=20240203T212839, end_date=20240203T212924
[2024-02-03T21:29:25.670+0000] {standard_task_runner.py:104} ERROR - Failed to execute job 7188 for task read_s3_data (Table 'old_customer200' already exists.; 4530)
[2024-02-03T21:29:25.902+0000] {local_task_job_runner.py:228} INFO - Task exited with return code 1
[2024-02-03T21:29:27.307+0000] {taskinstance.py:2776} INFO - 0 downstream tasks scheduled from follow-on schedule check
