[2023-07-11T00:15:12.810+0000] {taskinstance.py:1083} INFO - Dependencies all met for <TaskInstance: age_check.age_check scheduled__2023-07-10T00:00:00+00:00 [queued]>
[2023-07-11T00:15:12.818+0000] {taskinstance.py:1083} INFO - Dependencies all met for <TaskInstance: age_check.age_check scheduled__2023-07-10T00:00:00+00:00 [queued]>
[2023-07-11T00:15:12.819+0000] {taskinstance.py:1279} INFO - 
--------------------------------------------------------------------------------
[2023-07-11T00:15:12.824+0000] {taskinstance.py:1280} INFO - Starting attempt 2 of 4
[2023-07-11T00:15:12.825+0000] {taskinstance.py:1281} INFO - 
--------------------------------------------------------------------------------
[2023-07-11T00:15:12.833+0000] {taskinstance.py:1300} INFO - Executing <Task(PythonOperator): age_check> on 2023-07-10 00:00:00+00:00
[2023-07-11T00:15:12.843+0000] {standard_task_runner.py:55} INFO - Started process 78191 to run task
[2023-07-11T00:15:12.847+0000] {standard_task_runner.py:82} INFO - Running: ['***', 'tasks', 'run', 'age_check', 'age_check', 'scheduled__2023-07-10T00:00:00+00:00', '--job-id', '3645', '--raw', '--subdir', 'DAGS_FOLDER/age.py', '--cfg-path', '/tmp/tmp1ucmh47v']
[2023-07-11T00:15:12.849+0000] {standard_task_runner.py:83} INFO - Job 3645: Subtask age_check
[2023-07-11T00:15:12.915+0000] {task_command.py:388} INFO - Running <TaskInstance: age_check.age_check scheduled__2023-07-10T00:00:00+00:00 [running]> on host 25f6b46723d1
[2023-07-11T00:15:12.978+0000] {taskinstance.py:1509} INFO - Exporting the following env vars:
AIRFLOW_CTX_DAG_OWNER=***
AIRFLOW_CTX_DAG_ID=age_check
AIRFLOW_CTX_TASK_ID=age_check
AIRFLOW_CTX_EXECUTION_DATE=2023-07-10T00:00:00+00:00
AIRFLOW_CTX_TRY_NUMBER=2
AIRFLOW_CTX_DAG_RUN_ID=scheduled__2023-07-10T00:00:00+00:00
[2023-07-11T00:15:12.990+0000] {taskinstance.py:1768} ERROR - Task failed with exception
Traceback (most recent call last):
  File "/home/airflow/.local/lib/python3.7/site-packages/airflow/operators/python.py", line 175, in execute
    return_value = self.execute_callable()
  File "/home/airflow/.local/lib/python3.7/site-packages/airflow/operators/python.py", line 192, in execute_callable
    return self.python_callable(*self.op_args, **self.op_kwargs)
  File "/opt/airflow/dags/age.py", line 35, in age_check
    birth_year = int(Variable.get('birth_year'))
  File "/home/airflow/.local/lib/python3.7/site-packages/airflow/models/variable.py", line 141, in get
    raise KeyError(f"Variable {key} does not exist")
KeyError: 'Variable birth_year does not exist'
[2023-07-11T00:15:13.003+0000] {taskinstance.py:1323} INFO - Marking task as UP_FOR_RETRY. dag_id=age_check, task_id=age_check, execution_date=20230710T000000, start_date=20230711T001512, end_date=20230711T001513
[2023-07-11T00:15:13.017+0000] {standard_task_runner.py:105} ERROR - Failed to execute job 3645 for task age_check ('Variable birth_year does not exist'; 78191)
[2023-07-11T00:15:13.063+0000] {local_task_job.py:208} INFO - Task exited with return code 1
[2023-07-11T00:15:13.091+0000] {taskinstance.py:2578} INFO - 0 downstream tasks scheduled from follow-on schedule check
