[2023-12-17T21:14:52.742+0000] {taskinstance.py:1157} INFO - Dependencies all met for dep_context=non-requeueable deps ti=<TaskInstance: read_s3_data.read_s3_data scheduled__2023-06-15T00:00:00+00:00 [queued]>
[2023-12-17T21:14:53.210+0000] {taskinstance.py:1157} INFO - Dependencies all met for dep_context=requeueable deps ti=<TaskInstance: read_s3_data.read_s3_data scheduled__2023-06-15T00:00:00+00:00 [queued]>
[2023-12-17T21:14:53.216+0000] {taskinstance.py:1359} INFO - Starting attempt 3 of 4
[2023-12-17T21:14:55.065+0000] {taskinstance.py:1380} INFO - Executing <Task(PythonOperator): read_s3_data> on 2023-06-15 00:00:00+00:00
[2023-12-17T21:14:55.176+0000] {standard_task_runner.py:57} INFO - Started process 942 to run task
[2023-12-17T21:14:55.432+0000] {standard_task_runner.py:84} INFO - Running: ['***', 'tasks', 'run', 'read_s3_data', 'read_s3_data', 'scheduled__2023-06-15T00:00:00+00:00', '--job-id', '7650', '--raw', '--subdir', 'DAGS_FOLDER/read.py', '--cfg-path', '/tmp/tmph6j4d8if']
[2023-12-17T21:14:55.486+0000] {standard_task_runner.py:85} INFO - Job 7650: Subtask read_s3_data
[2023-12-17T21:14:56.511+0000] {task_command.py:415} INFO - Running <TaskInstance: read_s3_data.read_s3_data scheduled__2023-06-15T00:00:00+00:00 [running]> on host 883df3d9b006
[2023-12-17T21:14:57.597+0000] {taskinstance.py:1660} INFO - Exporting env vars: AIRFLOW_CTX_DAG_OWNER='***' AIRFLOW_CTX_DAG_ID='read_s3_data' AIRFLOW_CTX_TASK_ID='read_s3_data' AIRFLOW_CTX_EXECUTION_DATE='2023-06-15T00:00:00+00:00' AIRFLOW_CTX_TRY_NUMBER='3' AIRFLOW_CTX_DAG_RUN_ID='scheduled__2023-06-15T00:00:00+00:00'
[2023-12-17T21:14:57.649+0000] {taskinstance.py:1935} ERROR - Task failed with exception
Traceback (most recent call last):
  File "/home/airflow/.local/lib/python3.11/site-packages/airflow/operators/python.py", line 192, in execute
    return_value = self.execute_callable()
                   ^^^^^^^^^^^^^^^^^^^^^^^
  File "/home/airflow/.local/lib/python3.11/site-packages/airflow/operators/python.py", line 209, in execute_callable
    return self.python_callable(*self.op_args, **self.op_kwargs)
           ^^^^^^^^^^^^^^^^^^^^^^^^^^^^^^^^^^^^^^^^^^^^^^^^^^^^^
TypeError: generic_s3_clients() missing 2 required positional arguments: 'ACCESS_KEY' and 'SECRET_KEY'
[2023-12-17T21:14:57.747+0000] {taskinstance.py:1398} INFO - Marking task as UP_FOR_RETRY. dag_id=read_s3_data, task_id=read_s3_data, execution_date=20230615T000000, start_date=20231217T211452, end_date=20231217T211457
[2023-12-17T21:14:57.866+0000] {standard_task_runner.py:104} ERROR - Failed to execute job 7650 for task read_s3_data (generic_s3_clients() missing 2 required positional arguments: 'ACCESS_KEY' and 'SECRET_KEY'; 942)
[2023-12-17T21:14:58.203+0000] {local_task_job_runner.py:228} INFO - Task exited with return code 1
[2023-12-17T21:14:58.576+0000] {taskinstance.py:2776} INFO - 0 downstream tasks scheduled from follow-on schedule check
[2024-01-20T15:21:41.155+0000] {taskinstance.py:1157} INFO - Dependencies all met for dep_context=non-requeueable deps ti=<TaskInstance: read_s3_data.read_s3_data scheduled__2023-06-15T00:00:00+00:00 [queued]>
[2024-01-20T15:21:41.162+0000] {taskinstance.py:1157} INFO - Dependencies all met for dep_context=requeueable deps ti=<TaskInstance: read_s3_data.read_s3_data scheduled__2023-06-15T00:00:00+00:00 [queued]>
[2024-01-20T15:21:41.163+0000] {taskinstance.py:1359} INFO - Starting attempt 3 of 4
[2024-01-20T15:21:41.170+0000] {taskinstance.py:1380} INFO - Executing <Task(PythonOperator): read_s3_data> on 2023-06-15 00:00:00+00:00
[2024-01-20T15:21:41.176+0000] {standard_task_runner.py:57} INFO - Started process 64300 to run task
[2024-01-20T15:21:41.180+0000] {standard_task_runner.py:84} INFO - Running: ['***', 'tasks', 'run', 'read_s3_data', 'read_s3_data', 'scheduled__2023-06-15T00:00:00+00:00', '--job-id', '1676', '--raw', '--subdir', 'DAGS_FOLDER/read.py', '--cfg-path', '/tmp/tmpffwz4gr_']
[2024-01-20T15:21:41.183+0000] {standard_task_runner.py:85} INFO - Job 1676: Subtask read_s3_data
[2024-01-20T15:21:41.233+0000] {task_command.py:415} INFO - Running <TaskInstance: read_s3_data.read_s3_data scheduled__2023-06-15T00:00:00+00:00 [running]> on host dbb3489df186
[2024-01-20T15:21:41.289+0000] {taskinstance.py:1660} INFO - Exporting env vars: AIRFLOW_CTX_DAG_OWNER='***' AIRFLOW_CTX_DAG_ID='read_s3_data' AIRFLOW_CTX_TASK_ID='read_s3_data' AIRFLOW_CTX_EXECUTION_DATE='2023-06-15T00:00:00+00:00' AIRFLOW_CTX_TRY_NUMBER='3' AIRFLOW_CTX_DAG_RUN_ID='scheduled__2023-06-15T00:00:00+00:00'
[2024-01-20T15:23:11.183+0000] {taskinstance.py:1935} ERROR - Task failed with exception
Traceback (most recent call last):
  File "/home/airflow/.local/lib/python3.11/site-packages/airflow/operators/python.py", line 192, in execute
    return_value = self.execute_callable()
                   ^^^^^^^^^^^^^^^^^^^^^^^
  File "/home/airflow/.local/lib/python3.11/site-packages/airflow/operators/python.py", line 209, in execute_callable
    return self.python_callable(*self.op_args, **self.op_kwargs)
           ^^^^^^^^^^^^^^^^^^^^^^^^^^^^^^^^^^^^^^^^^^^^^^^^^^^^^
  File "/opt/airflow/dags/read.py", line 40, in read_s3_file
    cnxn = create_engine("postgresql+psycopg2://staging_db:DnrbWdUcaZxyIc7v:5432/main")
           ^^^^^^^^^^^^^^^^^^^^^^^^^^^^^^^^^^^^^^^^^^^^^^^^^^^^^^^^^^^^^^^^^^^^^^^^^^^^
  File "<string>", line 2, in create_engine
  File "/home/airflow/.local/lib/python3.11/site-packages/sqlalchemy/util/deprecations.py", line 375, in warned
    return fn(*args, **kwargs)
           ^^^^^^^^^^^^^^^^^^^
  File "/home/airflow/.local/lib/python3.11/site-packages/sqlalchemy/engine/create.py", line 514, in create_engine
    u = _url.make_url(url)
        ^^^^^^^^^^^^^^^^^^
  File "/home/airflow/.local/lib/python3.11/site-packages/sqlalchemy/engine/url.py", line 738, in make_url
    return _parse_url(name_or_url)
           ^^^^^^^^^^^^^^^^^^^^^^^
  File "/home/airflow/.local/lib/python3.11/site-packages/sqlalchemy/engine/url.py", line 794, in _parse_url
    components["port"] = int(components["port"])
                         ^^^^^^^^^^^^^^^^^^^^^^^
ValueError: invalid literal for int() with base 10: 'DnrbWdUcaZxyIc7v:5432'
[2024-01-20T15:23:11.212+0000] {taskinstance.py:1398} INFO - Marking task as UP_FOR_RETRY. dag_id=read_s3_data, task_id=read_s3_data, execution_date=20230615T000000, start_date=20240120T152141, end_date=20240120T152311
[2024-01-20T15:23:11.228+0000] {standard_task_runner.py:104} ERROR - Failed to execute job 1676 for task read_s3_data (invalid literal for int() with base 10: 'DnrbWdUcaZxyIc7v:5432'; 64300)
[2024-01-20T15:23:11.272+0000] {local_task_job_runner.py:228} INFO - Task exited with return code 1
[2024-01-20T15:23:11.290+0000] {taskinstance.py:2776} INFO - 0 downstream tasks scheduled from follow-on schedule check
