[2023-12-17T16:17:55.620+0000] {taskinstance.py:1157} INFO - Dependencies all met for dep_context=non-requeueable deps ti=<TaskInstance: read_s3_data.read_s3_data scheduled__2023-01-09T00:00:00+00:00 [queued]>
[2023-12-17T16:17:56.408+0000] {taskinstance.py:1157} INFO - Dependencies all met for dep_context=requeueable deps ti=<TaskInstance: read_s3_data.read_s3_data scheduled__2023-01-09T00:00:00+00:00 [queued]>
[2023-12-17T16:17:56.434+0000] {taskinstance.py:1359} INFO - Starting attempt 4 of 4
[2023-12-17T16:17:56.771+0000] {taskinstance.py:1380} INFO - Executing <Task(PythonOperator): read_s3_data> on 2023-01-09 00:00:00+00:00
[2023-12-17T16:17:57.461+0000] {standard_task_runner.py:84} INFO - Running: ['***', 'tasks', 'run', 'read_s3_data', 'read_s3_data', 'scheduled__2023-01-09T00:00:00+00:00', '--job-id', '6976', '--raw', '--subdir', 'DAGS_FOLDER/read.py', '--cfg-path', '/tmp/tmpjkgher6e']
[2023-12-17T16:17:57.484+0000] {standard_task_runner.py:85} INFO - Job 6976: Subtask read_s3_data
[2023-12-17T16:17:57.276+0000] {standard_task_runner.py:57} INFO - Started process 29021 to run task
[2023-12-17T16:18:05.000+0000] {task_command.py:415} INFO - Running <TaskInstance: read_s3_data.read_s3_data scheduled__2023-01-09T00:00:00+00:00 [running]> on host 533efb53d454
[2023-12-17T16:18:29.293+0000] {taskinstance.py:1660} INFO - Exporting env vars: AIRFLOW_CTX_DAG_OWNER='***' AIRFLOW_CTX_DAG_ID='read_s3_data' AIRFLOW_CTX_TASK_ID='read_s3_data' AIRFLOW_CTX_EXECUTION_DATE='2023-01-09T00:00:00+00:00' AIRFLOW_CTX_TRY_NUMBER='4' AIRFLOW_CTX_DAG_RUN_ID='scheduled__2023-01-09T00:00:00+00:00'
[2023-12-17T16:18:29.669+0000] {taskinstance.py:1935} ERROR - Task failed with exception
Traceback (most recent call last):
  File "/home/airflow/.local/lib/python3.11/site-packages/airflow/operators/python.py", line 192, in execute
    return_value = self.execute_callable()
                   ^^^^^^^^^^^^^^^^^^^^^^^
  File "/home/airflow/.local/lib/python3.11/site-packages/airflow/operators/python.py", line 209, in execute_callable
    return self.python_callable(*self.op_args, **self.op_kwargs)
           ^^^^^^^^^^^^^^^^^^^^^^^^^^^^^^^^^^^^^^^^^^^^^^^^^^^^^
TypeError: generic_s3_clients() missing 2 required positional arguments: 'ACCESS_KEY' and 'SECRET_KEY'
[2023-12-17T16:18:29.951+0000] {taskinstance.py:1398} INFO - Marking task as FAILED. dag_id=read_s3_data, task_id=read_s3_data, execution_date=20230109T000000, start_date=20231217T161755, end_date=20231217T161829
[2023-12-17T16:18:30.612+0000] {standard_task_runner.py:104} ERROR - Failed to execute job 6976 for task read_s3_data (generic_s3_clients() missing 2 required positional arguments: 'ACCESS_KEY' and 'SECRET_KEY'; 29021)
[2023-12-17T16:18:36.733+0000] {local_task_job_runner.py:228} INFO - Task exited with return code 1
[2023-12-17T16:18:39.710+0000] {taskinstance.py:2776} INFO - 0 downstream tasks scheduled from follow-on schedule check
